Workbook

Sheet Инструкция
A1: Положение по оплате труда (ПОТ) — инструкция по заполнению шаблона
A2: Версия шаблона: 1.1. Для кого: сотрудники отдела C&B (заполнение), команда Хранилища данных (загрузка и расчёт).
A4: 1. Назначение
A5: Файл описывает ПОТ — набор премий переменной части ЗП и правила их расчёта. Набор премий задаётся для сочетания пяти атрибутов сотрудника: ДЦ + ЦФО + подразделение + марка + должность. Хранилище данных загружает файл как справочник ПОТ. Затем Хранилище считает премию каждому сотруднику по плановым и фактическим значениям KPI и % их выполнения. Файл НЕ содержит данных по сотрудникам и фактических значений KPI. Эти данные хранятся в Хранилище.
A7: 2. Термины
A8: Термин | B8: Значение
A9: ПОТ | B9: Одна строка листа ПОТ_Премии: одна премия для одного сочетания атрибутов на период действия.
A10: код_ПОТ | B10: Уникальный код строки ПОТ. Формат: ПОТ-NNN. Не меняется после загрузки в Хранилище.
A11: KPI_расчёта | B11: Показатель, который умножается на множитель. Это может быть факт KPI, план KPI или плановое значение премии.
A12: KPI_шкалы | B12: Показатель, по значению которого выбирается ступень шкалы. Обычно это факт KPI или % выполнения плана.
A13: Тип значения | B13: Какое значение KPI брать из Хранилища: Факт, План или % выполнения плана.
A14: Шкала | B14: Набор ступеней. Одну шкалу можно использовать в нескольких строках ПОТ.
A15: Ступень | B15: Диапазон значений KPI_шкалы и множитель для этого диапазона.
A16: Множитель | B16: Число, на которое умножается KPI_расчёта. Задаётся в ступени шкалы.
A17: Справочник | B17: Список допустимых значений с кодами (ДЦ, ЦФО, KPI и т.д.). Источник — Хранилище / SAP HR.
A19: 3. Формула расчёта премии
A20: Премия = значение KPI_расчёта × Множитель
A21: Порядок расчёта: 1) Хранилище берёт значение KPI_шкалы (X) нужного типа за период. 2) Хранилище находит ступень шкалы, для которой: значение_от ≤ X < значение_до. Если значение_до пусто, верхней границы нет. 3) Если тип множителя = «Число», множитель берётся из столбца «множитель». Если тип = «Значение KPI шкалы», множитель = X. 4) Премия = значение KPI_расчёта × множитель. Переменная часть ЗП = сумма премий сотрудника за период.
A22: Примеры (по условиям задания)
A23: Премия | B23: KPI_расчёта | C23: KPI_шкалы (X) | D23: Ступень | E23: Расчёт
A24: Премия за количество новых АМ | B24: Кол-во проданных АМ, факт = 10 | C24: Кол-во проданных АМ, факт = 10 | D24: 6 ≤ 10 < 15 → 15 000 | E24: 10 × 15 000 = 150 000
A25: Премия за кумулятивную маржу | B25: Кумулятивная маржа, факт = 12 000 000 | C25: Кол-во проданных АМ, факт = 12 | D25: 6 ≤ 12 < 15 → 0,04 | E25: 12 000 000 × 0,04 = 480 000
A26: Премия за маржу сервиса | B26: Маржа сервиса, факт = 800 000 | C26: % выполнения плана маржи = 95 % | D26: 80 % ≤ 95 % < 120 % → множитель = X = 0,95 | E26: 800 000 × 0,95 = 760 000
A27: Премия за КВ фин. услуг | B27: Плановая премия за КВ, план = 50 000 | C27: % выполнения плана КВ = 76 % | D27: 0 ≤ 76 % < 80 % → 0,5 | E27: 50 000 × 0,5 = 25 000
A29: 4. Структура файла
A30: Лист | B30: Назначение | D30: Кто заполняет | E30: Читает ETL | F30: Примечание
A31: Инструкция | B31: Этот документ. | D31: — | E31: Нет
A32: ПОТ_Премии | B32: Основная таблица: премии для сочетаний атрибутов. | D32: C&B | E32: Да (pot_bonus) | F32: Столбцы с кодами скрыты.
A33: Справочники | B33: 10 справочников с кодами. | D33: Хранилище / администратор | E33: Да (ref_*), для сверки | F33: C&B не меняет. Новое значение — заявка в Хранилище.
A34: Шкалы | B34: Список шкал. | D34: C&B | E34: Да (scale)
A35: Шкалы_ступени | B35: Ступени всех шкал. | D35: C&B | E35: Да (scale_step)
A36: Проверки | B36: Итог проверок. Должно быть «ДА». | D36: — (авто) | E36: Нет
A37: Описание_полей | B37: Описание каждого столбца: тип, правило, пример. | D37: — | E37: Нет
A38: Пример_расчёта | B38: Демонстрация расчёта по сотрудникам. | D38: — | E38: Нет | F38: Только для понимания. Можно менять для проверки шкал.
A40: 5. Общие правила
A41: Правило | E41: Почему
A42: Вводите данные только в жёлтые ячейки. Серые ячейки считаются автоматически. | E42: Серые ячейки содержат формулы кодов и проверок.
A43: Выбирайте значения из выпадающих списков. Не вводите текст вручную. | E43: ETL связывает таблицы по кодам. Опечатка = значение не найдено.
A44: Новую строку добавляйте сразу под последней строкой таблицы. Таблица расширится сама. | E44: Строки вне таблицы ETL не читает.
A45: Не оставляйте пустые строки внутри таблицы. | E45: Пустая строка = ошибка загрузки.
...

Sheet ПОТ_Премии
A1: код_ПОТ | B1: ДЦ | C1: код_ДЦ | D1: ЦФО | E1: код_ЦФО | F1: подразделение | G1: код_подразделения | H1: марка | I1: код_марки | J1: должность | K1: код_должности | L1: вид_премии | M1: код_вида_премии | N1: периодичность | O1: код_периодичности | P1: KPI_расчёта | Q1: код_KPI_расчёта | R1: тип_значения_KPI_расчёта | S1: код_типа_KPI_расчёта | T1: KPI_шкалы | U1: код_KPI_шкалы | V1: тип_значения_KPI_шкалы | W1: код_типа_KPI_шкалы | X1: шкала | Y1: код_шкалы | Z1: дата_начала | AA1: дата_окончания | AB1: комментарий | AC1: проверка
A2: ПОТ-001 | B2: ДЦ Север | C2: =IF(B2="","",IFERROR(INDEX(Справочники!$A$2:$A$500,MATCH(B2,Справочники!$B$2:$B$500,0)),"!нет в справочнике")) -> DC-01 | D2: Продажи новых АМ | E2: =IF(D2="","",IFERROR(INDEX(Справочники!$D$2:$D$500,MATCH(D2,Справочники!$E$2:$E$500,0)),"!нет в справочнике")) -> CFO-01 | F2: Отдел продаж новых АМ | G2: =IF(F2="","",IFERROR(INDEX(Справочники!$G$2:$G$500,MATCH(F2,Справочники!$H$2:$H$500,0)),"!нет в справочнике")) -> DEP-01 | H2: Haval | I2: =IF(H2="","",IFERROR(INDEX(Справочники!$J$2:$J$500,MATCH(H2,Справочники!$K$2:$K$500,0)),"!нет в справочнике")) -> BR-01 | J2: Менеджер по продажам новых АМ | K2: =IF(J2="","",IFERROR(INDEX(Справочники!$M$2:$M$500,MATCH(J2,Справочники!$N$2:$N$500,0)),"!нет в справочнике")) -> POS-001 | L2: Премия за количество новых АМ | M2: =IF(L2="","",IFERROR(INDEX(Справочники!$P$2:$P$500,MATCH(L2,Справочники!$Q$2:$Q$500,0)),"!нет в справочнике")) -> BT-001 | N2: Ежемесячно | O2: =IF(N2="","",IFERROR(INDEX(Справочники!$W$2:$W$500,MATCH(N2,Справочники!$X$2:$X$500,0)),"!нет в справочнике")) -> MONTH | P2: Кол-во проданных новых АМ | Q2: =IF(P2="","",IFERROR(INDEX(Справочники!$S$2:$S$500,MATCH(P2,Справочники!$T$2:$T$500,0)),"!нет в справочнике")) -> KPI-001 | R2: Факт | S2: =IF(R2="","",IFERROR(INDEX(Справочники!$Z$2:$Z$500,MATCH(R2,Справочники!$AA$2:$AA$500,0)),"!нет в справочнике")) -> FACT | T2: Кол-во проданных новых АМ | U2: =IF(T2="","",IFERROR(INDEX(Справочники!$S$2:$S$500,MATCH(T2,Справочники!$T$2:$T$500,0)),"!нет в справочнике")) -> KPI-001 | V2: Факт | W2: =IF(V2="","",IFERROR(INDEX(Справочники!$Z$2:$Z$500,MATCH(V2,Справочники!$AA$2:$AA$500,0)),"!нет в справочнике")) -> FACT | X2: Кол-во новых АМ → сумма за 1 АМ | Y2: =IF(X2="","",IFERROR(INDEX(Шкалы!$A$2:$A$500,MATCH(X2,Шкалы!$B$2:$B$500,0)),"!нет в справочнике")) -> SC-001 | Z2: 46023 | AC2: =IF(A2="","",IF(COUNTIF($A$2:$A$500,A2)>1,"Дубль код_ПОТ",IF(COUNTBLANK(B2:Z2)>0,"Не заполнены обязательные поля",IF(COUNTIF(C2:Y2,"!*")>0,"Значение не найдено в справочнике",IF(AND(AA2<>"",N(AA2)<N(Z2)),"дата_окончания раньше дата_начала",IF(COUNTIF(Шкалы_ступени!$B$2:$B$500,Y2)=0,"У шкалы нет ступеней",IF(SUMPRODUCT(($C$2:$C$500=C2)*($E$2:$E$500=E2)*($G$2:$G$500=G2)*($I$2:$I$500=I2)*($K$2:$K$500=K2)*($M$2:$M$500=M2)*(ROW($A$2:$A$500)<>ROW())*($Z$2:$Z$500<=(AA2="")*1E+99+N(AA2))*((($AA$2:$AA$500="")*1E+99+$AA$2:$AA$500)>=N(Z2)))>0,"Пересечение со строкой с тем же набором атрибутов","ОК"))))))) -> ОК
A3: ПОТ-002 | B3: ДЦ Север | C3: =IF(B3="","",IFERROR(INDEX(Справочники!$A$2:$A$500,MATCH(B3,Справочники!$B$2:$B$500,0)),"!нет в справочнике")) -> DC-01 | D3: Продажи новых АМ | E3: =IF(D3="","",IFERROR(INDEX(Справочники!$D$2:$D$500,MATCH(D3,Справочники!$E$2:$E$500,0)),"!нет в справочнике")) -> CFO-01 | F3: Отдел продаж новых АМ | G3: =IF(F3="","",IFERROR(INDEX(Справочники!$G$2:$G$500,MATCH(F3,Справочники!$H$2:$H$500,0)),"!нет в справочнике")) -> DEP-01 | H3: Haval | I3: =IF(H3="","",IFERROR(INDEX(Справочники!$J$2:$J$500,MATCH(H3,Справочники!$K$2:$K$500,0)),"!нет в справочнике")) -> BR-01 | J3: Менеджер по продажам новых АМ | K3: =IF(J3="","",IFERROR(INDEX(Справочники!$M$2:$M$500,MATCH(J3,Справочники!$N$2:$N$500,0)),"!нет в справочнике")) -> POS-001 | L3: Премия за кумулятивную маржу при продаже новых АМ | M3: =IF(L3="","",IFERROR(INDEX(Справочники!$P$2:$P$500,MATCH(L3,Справочники!$Q$2:$Q$500,0)),"!нет в справочнике")) -> BT-002 | N3: Ежемесячно | O3: =IF(N3="","",IFERROR(INDEX(Справочники!$W$2:$W$500,MATCH(N3,Справочники!$X$2:$X$500,0)),"!нет в справочнике")) -> MONTH | P3: Кумулятивная маржа при продаже новых АМ | Q3: =IF(P3="","",IFERROR(INDEX(Справочники!$S$2:$S$500,MATCH(P3,Справочники!$T$2:$T$500,0)),"!нет в справочнике")) -> KPI-002 | R3: Факт | S3: =IF(R3="","",IFERROR(INDEX(Справочники!$Z$2:$Z$500,MATCH(R3,Справочники!$AA$2:$AA$500,0)),"!нет в справочнике")) -> FACT | T3: Кол-во проданных новых АМ | U3: =IF(T3="","",IFERROR(INDEX(Справочники!$S$2:$S$500,MATCH(T3,Справочники!$T$2:$T$500,0)),"!нет в справочнике")) -> KPI-001 | V3: Факт | W3: =IF(V3="","",IFERROR(INDEX(Справочники!$Z$2:$Z$500,MATCH(V3,Справочники!$AA$2:$AA$500,0)),"!нет в справочнике")) -> FACT | X3: Кол-во новых АМ → доля кумулятивной маржи | Y3: =IF(X3="","",IFERROR(INDEX(Шкалы!$A$2:$A$500,MATCH(X3,Шкалы!$B$2:$B$500,0)),"!нет в справочнике")) -> SC-002 | Z3: 46023 | AC3: =IF(A3="","",IF(COUNTIF($A$2:$A$500,A3)>1,"Дубль код_ПОТ",IF(COUNTBLANK(B3:Z3)>0,"Не заполнены обязательные поля",IF(COUNTIF(C3:Y3,"!*")>0,"Значение не найдено в справочнике",IF(AND(AA3<>"",N(AA3)<N(Z3)),"дата_окончания раньше дата_начала",IF(COUNTIF(Шкалы_ступени!$B$2:$B$500,Y3)=0,"У шкалы нет ступеней",IF(SUMPRODUCT(($C$2:$C$500=C3)*($E$2:$E$500=E3)*($G$2:$G$500=G3)*($I$2:$I$500=I3)*($K$2:$K$500=K3)*($M$2:$M$500=M3)*(ROW($A$2:$A$500)<>ROW())*($Z$2:$Z$500<=(AA3="")*1E+99+N(AA3))*((($AA$2:$AA$500="")*1E+99+$AA$2:$AA$500)>=N(Z3)))>0,"Пересечение со строкой с тем же набором атрибутов","ОК"))))))) -> ОК
A4: ПОТ-003 | B4: ДЦ Север | C4: =IF(B4="","",IFERROR(INDEX(Справочники!$A$2:$A$500,MATCH(B4,Справочники!$B$2:$B$500,0)),"!нет в справочнике")) -> DC-01 | D4: Продажи новых АМ | E4: =IF(D4="","",IFERROR(INDEX(Справочники!$D$2:$D$500,MATCH(D4,Справочники!$E$2:$E$500,0)),"!нет в справочнике")) -> CFO-01 | F4: Отдел продаж новых АМ | G4: =IF(F4="","",IFERROR(INDEX(Справочники!$G$2:$G$500,MATCH(F4,Справочники!$H$2:$H$500,0)),"!нет в справочнике")) -> DEP-01 | H4: Chery | I4: =IF(H4="","",IFERROR(INDEX(Справочники!$J$2:$J$500,MATCH(H4,Справочники!$K$2:$K$500,0)),"!нет в справочнике")) -> BR-02 | J4: Менеджер по продажам новых АМ | K4: =IF(J4="","",IFERROR(INDEX(Справочники!$M$2:$M$500,MATCH(J4,Справочники!$N$2:$N$500,0)),"!нет в справочнике")) -> POS-001 | L4: Премия за количество новых АМ | M4: =IF(L4="","",IFERROR(INDEX(Справочники!$P$2:$P$500,MATCH(L4,Справочники!$Q$2:$Q$500,0)),"!нет в справочнике")) -> BT-001 | N4: Ежемесячно | O4: =IF(N4="","",IFERROR(INDEX(Справочники!$W$2:$W$500,MATCH(N4,Справочники!$X$2:$X$500,0)),"!нет в справочнике")) -> MONTH | P4: Кол-во проданных новых АМ | Q4: =IF(P4="","",IFERROR(INDEX(Справочники!$S$2:$S$500,MATCH(P4,Справочники!$T$2:$T$500,0)),"!нет в справочнике")) -> KPI-001 | R4: Факт | S4: =IF(R4="","",IFERROR(INDEX(Справочники!$Z$2:$Z$500,MATCH(R4,Справочники!$AA$2:$AA$500,0)),"!нет в справочнике")) -> FACT | T4: Кол-во проданных новых АМ | U4: =IF(T4="","",IFERROR(INDEX(Справочники!$S$2:$S$500,MATCH(T4,Справочники!$T$2:$T$500,0)),"!нет в справочнике")) -> KPI-001 | V4: Факт | W4: =IF(V4="","",IFERROR(INDEX(Справочники!$Z$2:$Z$500,MATCH(V4,Справочники!$AA$2:$AA$500,0)),"!нет в справочнике")) -> FACT | X4: Кол-во новых АМ → сумма за 1 АМ | Y4: =IF(X4="","",IFERROR(INDEX(Шкалы!$A$2:$A$500,MATCH(X4,Шкалы!$B$2:$B$500,0)),"!нет в справочнике")) -> SC-001 | Z4: 46023 | AC4: =IF(A4="","",IF(COUNTIF($A$2:$A$500,A4)>1,"Дубль код_ПОТ",IF(COUNTBLANK(B4:Z4)>0,"Не заполнены обязательные поля",IF(COUNTIF(C4:Y4,"!*")>0,"Значение не найдено в справочнике",IF(AND(AA4<>"",N(AA4)<N(Z4)),"дата_окончания раньше дата_начала",IF(COUNTIF(Шкалы_ступени!$B$2:$B$500,Y4)=0,"У шкалы нет ступеней",IF(SUMPRODUCT(($C$2:$C$500=C4)*($E$2:$E$500=E4)*($G$2:$G$500=G4)*($I$2:$I$500=I4)*($K$2:$K$500=K4)*($M$2:$M$500=M4)*(ROW($A$2:$A$500)<>ROW())*($Z$2:$Z$500<=(AA4="")*1E+99+N(AA4))*((($AA$2:$AA$500="")*1E+99+$AA$2:$AA$500)>=N(Z4)))>0,"Пересечение со строкой с тем же набором атрибутов","ОК"))))))) -> ОК
A5: ПОТ-004 | B5: ДЦ Север | C5: =IF(B5="","",IFERROR(INDEX(Справочники!$A$2:$A$500,MATCH(B5,Справочники!$B$2:$B$500,0)),"!нет в справочнике")) -> DC-01 | D5: Продажи новых АМ | E5: =IF(D5="","",IFERROR(INDEX(Справочники!$D$2:$D$500,MATCH(D5,Справочники!$E$2:$E$500,0)),"!нет в справочнике")) -> CFO-01 | F5: Отдел продаж новых АМ | G5: =IF(F5="","",IFERROR(INDEX(Справочники!$G$2:$G$500,MATCH(F5,Справочники!$H$2:$H$500,0)),"!нет в справочнике")) -> DEP-01 | H5: Chery | I5: =IF(H5="","",IFERROR(INDEX(Справочники!$J$2:$J$500,MATCH(H5,Справочники!$K$2:$K$500,0)),"!нет в справочнике")) -> BR-02 | J5: Менеджер по продажам новых АМ | K5: =IF(J5="","",IFERROR(INDEX(Справочники!$M$2:$M$500,MATCH(J5,Справочники!$N$2:$N$500,0)),"!нет в справочнике")) -> POS-001 | L5: Премия за кумулятивную маржу при продаже новых АМ | M5: =IF(L5="","",IFERROR(INDEX(Справочники!$P$2:$P$500,MATCH(L5,Справочники!$Q$2:$Q$500,0)),"!нет в справочнике")) -> BT-002 | N5: Ежемесячно | O5: =IF(N5="","",IFERROR(INDEX(Справочники!$W$2:$W$500,MATCH(N5,Справочники!$X$2:$X$500,0)),"!нет в справочнике")) -> MONTH | P5: Кумулятивная маржа при продаже новых АМ | Q5: =IF(P5="","",IFERROR(INDEX(Справочники!$S$2:$S$500,MATCH(P5,Справочники!$T$2:$T$500,0)),"!нет в справочнике")) -> KPI-002 | R5: Факт | S5: =IF(R5="","",IFERROR(INDEX(Справочники!$Z$2:$Z$500,MATCH(R5,Справочники!$AA$2:$AA$500,0)),"!нет в справочнике")) -> FACT | T5: Кол-во проданных новых АМ | U5: =IF(T5="","",IFERROR(INDEX(Справочники!$S$2:$S$500,MATCH(T5,Справочники!$T$2:$T$500,0)),"!нет в справочнике")) -> KPI-001 | V5: Факт | W5: =IF(V5="","",IFERROR(INDEX(Справочники!$Z$2:$Z$500,MATCH(V5,Справочники!$AA$2:$AA$500,0)),"!нет в справочнике")) -> FACT | X5: Кол-во новых АМ → доля кумулятивной маржи | Y5: =IF(X5="","",IFERROR(INDEX(Шкалы!$A$2:$A$500,MATCH(X5,Шкалы!$B$2:$B$500,0)),"!нет в справочнике")) -> SC-002 | Z5: 46023 | AC5: =IF(A5="","",IF(COUNTIF($A$2:$A$500,A5)>1,"Дубль код_ПОТ",IF(COUNTBLANK(B5:Z5)>0,"Не заполнены обязательные поля",IF(COUNTIF(C5:Y5,"!*")>0,"Значение не найдено в справочнике",IF(AND(AA5<>"",N(AA5)<N(Z5)),"дата_окончания раньше дата_начала",IF(COUNTIF(Шкалы_ступени!$B$2:$B$500,Y5)=0,"У шкалы нет ступеней",IF(SUMPRODUCT(($C$2:$C$500=C5)*($E$2:$E$500=E5)*($G$2:$G$500=G5)*($I$2:$I$500=I5)*($K$2:$K$500=K5)*($M$2:$M$500=M5)*(ROW($A$2:$A$500)<>ROW())*($Z$2:$Z$500<=(AA5="")*1E+99+N(AA5))*((($AA$2:$AA$500="")*1E+99+$AA$2:$AA$500)>=N(Z5)))>0,"Пересечение со строкой с тем же набором атрибутов","ОК"))))))) -> ОК
A6: ПОТ-005 | B6: ДЦ Юг | C6: =IF(B6="","",IFERROR(INDEX(Справочники!$A$2:$A$500,MATCH(B6,Справочники!$B$2:$B$500,0)),"!нет в справочнике")) -> DC-02 | D6: Продажи новых АМ | E6: =IF(D6="","",IFERROR(INDEX(Справочники!$D$2:$D$500,MATCH(D6,Справочники!$E$2:$E$500,0)),"!нет в справочнике")) -> CFO-01 | F6: Отдел продаж новых АМ | G6: =IF(F6="","",IFERROR(INDEX(Справочники!$G$2:$G$500,MATCH(F6,Справочники!$H$2:$H$500,0)),"!нет в справочнике")) -> DEP-01 | H6: Geely | I6: =IF(H6="","",IFERROR(INDEX(Справочники!$J$2:$J$500,MATCH(H6,Справочники!$K$2:$K$500,0)),"!нет в справочнике")) -> BR-03 | J6: Менеджер по продажам новых АМ | K6: =IF(J6="","",IFERROR(INDEX(Справочники!$M$2:$M$500,MATCH(J6,Справочники!$N$2:$N$500,0)),"!нет в справочнике")) -> POS-001 | L6: Премия за количество новых АМ | M6: =IF(L6="","",IFERROR(INDEX(Справочники!$P$2:$P$500,MATCH(L6,Справочники!$Q$2:$Q$500,0)),"!нет в справочнике")) -> BT-001 | N6: Ежемесячно | O6: =IF(N6="","",IFERROR(INDEX(Справочники!$W$2:$W$500,MATCH(N6,Справочники!$X$2:$X$500,0)),"!нет в справочнике")) -> MONTH | P6: Кол-во проданных новых АМ | Q6: =IF(P6="","",IFERROR(INDEX(Справочники!$S$2:$S$500,MATCH(P6,Справочники!$T$2:$T$500,0)),"!нет в справочнике")) -> KPI-001 | R6: Факт | S6: =IF(R6="","",IFERROR(INDEX(Справочники!$Z$2:$Z$500,MATCH(R6,Справочники!$AA$2:$AA$500,0)),"!нет в справочнике")) -> FACT | T6: Кол-во проданных новых АМ | U6: =IF(T6="","",IFERROR(INDEX(Справочники!$S$2:$S$500,MATCH(T6,Справочники!$T$2:$T$500,0)),"!нет в справочнике")) -> KPI-001 | V6: Факт | W6: =IF(V6="","",IFERROR(INDEX(Справочники!$Z$2:$Z$500,MATCH(V6,Справочники!$AA$2:$AA$500,0)),"!нет в справочнике")) -> FACT | X6: Кол-во новых АМ → сумма за 1 АМ | Y6: =IF(X6="","",IFERROR(INDEX(Шкалы!$A$2:$A$500,MATCH(X6,Шкалы!$B$2:$B$500,0)),"!нет в справочнике")) -> SC-001 | Z6: 46023 | AC6: =IF(A6="","",IF(COUNTIF($A$2:$A$500,A6)>1,"Дубль код_ПОТ",IF(COUNTBLANK(B6:Z6)>0,"Не заполнены обязательные поля",IF(COUNTIF(C6:Y6,"!*")>0,"Значение не найдено в справочнике",IF(AND(AA6<>"",N(AA6)<N(Z6)),"дата_окончания раньше дата_начала",IF(COUNTIF(Шкалы_ступени!$B$2:$B$500,Y6)=0,"У шкалы нет ступеней",IF(SUMPRODUCT(($C$2:$C$500=C6)*($E$2:$E$500=E6)*($G$2:$G$500=G6)*($I$2:$I$500=I6)*($K$2:$K$500=K6)*($M$2:$M$500=M6)*(ROW($A$2:$A$500)<>ROW())*($Z$2:$Z$500<=(AA6="")*1E+99+N(AA6))*((($AA$2:$AA$500="")*1E+99+$AA$2:$AA$500)>=N(Z6)))>0,"Пересечение со строкой с тем же набором атрибутов","ОК"))))))) -> ОК
A7: ПОТ-006 | B7: ДЦ Север | C7: =IF(B7="","",IFERROR(INDEX(Справочники!$A$2:$A$500,MATCH(B7,Справочники!$B$2:$B$500,0)),"!нет в справочнике")) -> DC-01 | D7: Сервис | E7: =IF(D7="","",IFERROR(INDEX(Справочники!$D$2:$D$500,MATCH(D7,Справочники!$E$2:$E$500,0)),"!нет в справочнике")) -> CFO-03 | F7: Сервисный центр | G7: =IF(F7="","",IFERROR(INDEX(Справочники!$G$2:$G$500,MATCH(F7,Справочники!$H$2:$H$500,0)),"!нет в справочнике")) -> DEP-03 | H7: Haval | I7: =IF(H7="","",IFERROR(INDEX(Справочники!$J$2:$J$500,MATCH(H7,Справочники!$K$2:$K$500,0)),"!нет в справочнике")) -> BR-01 | J7: Мастер-консультант | K7: =IF(J7="","",IFERROR(INDEX(Справочники!$M$2:$M$500,MATCH(J7,Справочники!$N$2:$N$500,0)),"!нет в справочнике")) -> POS-002 | L7: Премия за маржу от продажи сервисных услуг | M7: =IF(L7="","",IFERROR(INDEX(Справочники!$P$2:$P$500,MATCH(L7,Справочники!$Q$2:$Q$500,0)),"!нет в справочнике")) -> BT-003 | N7: Ежемесячно | O7: =IF(N7="","",IFERROR(INDEX(Справочники!$W$2:$W$500,MATCH(N7,Справочники!$X$2:$X$500,0)),"!нет в справочнике")) -> MONTH | P7: Маржа от продажи сервисных услуг | Q7: =IF(P7="","",IFERROR(INDEX(Справочники!$S$2:$S$500,MATCH(P7,Справочники!$T$2:$T$500,0)),"!нет в справочнике")) -> KPI-003 | R7: Факт | S7: =IF(R7="","",IFERROR(INDEX(Справочники!$Z$2:$Z$500,MATCH(R7,Справочники!$AA$2:$AA$500,0)),"!нет в справочнике")) -> FACT | T7: Маржа от продажи сервисных услуг | U7: =IF(T7="","",IFERROR(INDEX(Справочники!$S$2:$S$500,MATCH(T7,Справочники!$T$2:$T$500,0)),"!нет в справочнике")) -> KPI-003 | V7: % выполнения плана | W7: =IF(V7="","",IFERROR(INDEX(Справочники!$Z$2:$Z$500,MATCH(V7,Справочники!$AA$2:$AA$500,0)),"!нет в справочнике")) -> PCT | X7: % вып. плана маржи сервиса → коэффициент | Y7: =IF(X7="","",IFERROR(INDEX(Шкалы!$A$2:$A$500,MATCH(X7,Шкалы!$B$2:$B$500,0)),"!нет в справочнике")) -> SC-003 | Z7: 46023 | AC7: =IF(A7="","",IF(COUNTIF($A$2:$A$500,A7)>1,"Дубль код_ПОТ",IF(COUNTBLANK(B7:Z7)>0,"Не заполнены обязательные поля",IF(COUNTIF(C7:Y7,"!*")>0,"Значение не найдено в справочнике",IF(AND(AA7<>"",N(AA7)<N(Z7)),"дата_окончания раньше дата_начала",IF(COUNTIF(Шкалы_ступени!$B$2:$B$500,Y7)=0,"У шкалы нет ступеней",IF(SUMPRODUCT(($C$2:$C$500=C7)*($E$2:$E$500=E7)*($G$2:$G$500=G7)*($I$2:$I$500=I7)*($K$2:$K$500=K7)*($M$2:$M$500=M7)*(ROW($A$2:$A$500)<>ROW())*($Z$2:$Z$500<=(AA7="")*1E+99+N(AA7))*((($AA$2:$AA$500="")*1E+99+$AA$2:$AA$500)>=N(Z7)))>0,"Пересечение со строкой с тем же набором атрибутов","ОК"))))))) -> ОК
A8: ПОТ-007 | B8: ДЦ Юг | C8: =IF(B8="","",IFERROR(INDEX(Справочники!$A$2:$A$500,MATCH(B8,Справочники!$B$2:$B$500,0)),"!нет в справочнике")) -> DC-02 | D8: Сервис | E8: =IF(D8="","",IFERROR(INDEX(Справочники!$D$2:$D$500,MATCH(D8,Справочники!$E$2:$E$500,0)),"!нет в справочнике")) -> CFO-03 | F8: Сервисный центр | G8: =IF(F8="","",IFERROR(INDEX(Справочники!$G$2:$G$500,MATCH(F8,Справочники!$H$2:$H$500,0)),"!нет в справочнике")) -> DEP-03 | H8: Не определена | I8: =IF(H8="","",IFERROR(INDEX(Справочники!$J$2:$J$500,MATCH(H8,Справочники!$K$2:$K$500,0)),"!нет в справочнике")) -> BR-00 | J8: Мастер-консультант | K8: =IF(J8="","",IFERROR(INDEX(Справочники!$M$2:$M$500,MATCH(J8,Справочники!$N$2:$N$500,0)),"!нет в справочнике")) -> POS-002 | L8: Премия за маржу от продажи сервисных услуг | M8: =IF(L8="","",IFERROR(INDEX(Справочники!$P$2:$P$500,MATCH(L8,Справочники!$Q$2:$Q$500,0)),"!нет в справочнике")) -> BT-003 | N8: Ежемесячно | O8: =IF(N8="","",IFERROR(INDEX(Справочники!$W$2:$W$500,MATCH(N8,Справочники!$X$2:$X$500,0)),"!нет в справочнике")) -> MONTH | P8: Маржа от продажи сервисных услуг | Q8: =IF(P8="","",IFERROR(INDEX(Справочники!$S$2:$S$500,MATCH(P8,Справочники!$T$2:$T$500,0)),"!нет в справочнике")) -> KPI-003 | R8: Факт | S8: =IF(R8="","",IFERROR(INDEX(Справочники!$Z$2:$Z$500,MATCH(R8,Справочники!$AA$2:$AA$500,0)),"!нет в справочнике")) -> FACT | T8: Маржа от продажи сервисных услуг | U8: =IF(T8="","",IFERROR(INDEX(Справочники!$S$2:$S$500,MATCH(T8,Справочники!$T$2:$T$500,0)),"!нет в справочнике")) -> KPI-003 | V8: % выполнения плана | W8: =IF(V8="","",IFERROR(INDEX(Справочники!$Z$2:$Z$500,MATCH(V8,Справочники!$AA$2:$AA$500,0)),"!нет в справочнике")) -> PCT | X8: % вып. плана маржи сервиса → коэффициент | Y8: =IF(X8="","",IFERROR(INDEX(Шкалы!$A$2:$A$500,MATCH(X8,Шкалы!$B$2:$B$500,0)),"!нет в справочнике")) -> SC-003 | Z8: 46023 | AC8: =IF(A8="","",IF(COUNTIF($A$2:$A$500,A8)>1,"Дубль код_ПОТ",IF(COUNTBLANK(B8:Z8)>0,"Не заполнены обязательные поля",IF(COUNTIF(C8:Y8,"!*")>0,"Значение не найдено в справочнике",IF(AND(AA8<>"",N(AA8)<N(Z8)),"дата_окончания раньше дата_начала",IF(COUNTIF(Шкалы_ступени!$B$2:$B$500,Y8)=0,"У шкалы нет ступеней",IF(SUMPRODUCT(($C$2:$C$500=C8)*($E$2:$E$500=E8)*($G$2:$G$500=G8)*($I$2:$I$500=I8)*($K$2:$K$500=K8)*($M$2:$M$500=M8)*(ROW($A$2:$A$500)<>ROW())*($Z$2:$Z$500<=(AA8="")*1E+99+N(AA8))*((($AA$2:$AA$500="")*1E+99+$AA$2:$AA$500)>=N(Z8)))>0,"Пересечение со строкой с тем же набором атрибутов","ОК"))))))) -> ОК
A9: ПОТ-008 | B9: ДЦ Север | C9: =IF(B9="","",IFERROR(INDEX(Справочники!$A$2:$A$500,MATCH(B9,Справочники!$B$2:$B$500,0)),"!нет в справочнике")) -> DC-01 | D9: Финансовые услуги | E9: =IF(D9="","",IFERROR(INDEX(Справочники!$D$2:$D$500,MATCH(D9,Справочники!$E$2:$E$500,0)),"!нет в справочнике")) -> CFO-02 | F9: Отдел кредитования и страхования | G9: =IF(F9="","",IFERROR(INDEX(Справочники!$G$2:$G$500,MATCH(F9,Справочники!$H$2:$H$500,0)),"!нет в справочнике")) -> DEP-02 | H9: Не определена | I9: =IF(H9="","",IFERROR(INDEX(Справочники!$J$2:$J$500,MATCH(H9,Справочники!$K$2:$K$500,0)),"!нет в справочнике")) -> BR-00 | J9: Менеджер по кредитованию и страхованию | K9: =IF(J9="","",IFERROR(INDEX(Справочники!$M$2:$M$500,MATCH(J9,Справочники!$N$2:$N$500,0)),"!нет в справочнике")) -> POS-003 | L9: Премия за КВ от продажи финансовых услуг | M9: =IF(L9="","",IFERROR(INDEX(Справочники!$P$2:$P$500,MATCH(L9,Справочники!$Q$2:$Q$500,0)),"!нет в справочнике")) -> BT-004 | N9: Ежеквартально | O9: =IF(N9="","",IFERROR(INDEX(Справочники!$W$2:$W$500,MATCH(N9,Справочники!$X$2:$X$500,0)),"!нет в справочнике")) -> QUARTER | P9: Премия за КВ от продажи финансовых услуг | Q9: =IF(P9="","",IFERROR(INDEX(Справочники!$S$2:$S$500,MATCH(P9,Справочники!$T$2:$T$500,0)),"!нет в справочнике")) -> KPI-005 | R9: План | S9: =IF(R9="","",IFERROR(INDEX(Справочники!$Z$2:$Z$500,MATCH(R9,Справочники!$AA$2:$AA$500,0)),"!нет в справочнике")) -> PLAN | T9: КВ от продажи финансовых услуг | U9: =IF(T9="","",IFERROR(INDEX(Справочники!$S$2:$S$500,MATCH(T9,Справочники!$T$2:$T$500,0)),"!нет в справочнике")) -> KPI-004 | V9: % выполнения плана | W9: =IF(V9="","",IFERROR(INDEX(Справочники!$Z$2:$Z$500,MATCH(V9,Справочники!$AA$2:$AA$500,0)),"!нет в справочнике")) -> PCT | X9: % вып. плана КВ фин. услуг → коэффициент | Y9: =IF(X9="","",IFERROR(INDEX(Шкалы!$A$2:$A$500,MATCH(X9,Шкалы!$B$2:$B$500,0)),"!нет в справочнике")) -> SC-004 | Z9: 46023 | AC9: =IF(A9="","",IF(COUNTIF($A$2:$A$500,A9)>1,"Дубль код_ПОТ",IF(COUNTBLANK(B9:Z9)>0,"Не заполнены обязательные поля",IF(COUNTIF(C9:Y9,"!*")>0,"Значение не найдено в справочнике",IF(AND(AA9<>"",N(AA9)<N(Z9)),"дата_окончания раньше дата_начала",IF(COUNTIF(Шкалы_ступени!$B$2:$B$500,Y9)=0,"У шкалы нет ступеней",IF(SUMPRODUCT(($C$2:$C$500=C9)*($E$2:$E$500=E9)*($G$2:$G$500=G9)*($I$2:$I$500=I9)*($K$2:$K$500=K9)*($M$2:$M$500=M9)*(ROW($A$2:$A$500)<>ROW())*($Z$2:$Z$500<=(AA9="")*1E+99+N(AA9))*((($AA$2:$AA$500="")*1E+99+$AA$2:$AA$500)>=N(Z9)))>0,"Пересечение со строкой с тем же набором атрибутов","ОК"))))))) -> ОК
A10: ПОТ-009 | B10: ДЦ Запад | C10: =IF(B10="","",IFERROR(INDEX(Справочники!$A$2:$A$500,MATCH(B10,Справочники!$B$2:$B$500,0)),"!нет в справочнике")) -> DC-03 | D10: Финансовые услуги | E10: =IF(D10="","",IFERROR(INDEX(Справочники!$D$2:$D$500,MATCH(D10,Справочники!$E$2:$E$500,0)),"!нет в справочнике")) -> CFO-02 | F10: Отдел кредитования и страхования | G10: =IF(F10="","",IFERROR(INDEX(Справочники!$G$2:$G$500,MATCH(F10,Справочники!$H$2:$H$500,0)),"!нет в справочнике")) -> DEP-02 | H10: Не определена | I10: =IF(H10="","",IFERROR(INDEX(Справочники!$J$2:$J$500,MATCH(H10,Справочники!$K$2:$K$500,0)),"!нет в справочнике")) -> BR-00 | J10: Менеджер по кредитованию и страхованию | K10: =IF(J10="","",IFERROR(INDEX(Справочники!$M$2:$M$500,MATCH(J10,Справочники!$N$2:$N$500,0)),"!нет в справочнике")) -> POS-003 | L10: Премия за КВ от продажи финансовых услуг | M10: =IF(L10="","",IFERROR(INDEX(Справочники!$P$2:$P$500,MATCH(L10,Справочники!$Q$2:$Q$500,0)),"!нет в справочнике")) -> BT-004 | N10: Ежеквартально | O10: =IF(N10="","",IFERROR(INDEX(Справочники!$W$2:$W$500,MATCH(N10,Справочники!$X$2:$X$500,0)),"!нет в справочнике")) -> QUARTER | P10: Премия за КВ от продажи финансовых услуг | Q10: =IF(P10="","",IFERROR(INDEX(Справочники!$S$2:$S$500,MATCH(P10,Справочники!$T$2:$T$500,0)),"!нет в справочнике")) -> KPI-005 | R10: План | S10: =IF(R10="","",IFERROR(INDEX(Справочники!$Z$2:$Z$500,MATCH(R10,Справочники!$AA$2:$AA$500,0)),"!нет в справочнике")) -> PLAN | T10: КВ от продажи финансовых услуг | U10: =IF(T10="","",IFERROR(INDEX(Справочники!$S$2:$S$500,MATCH(T10,Справочники!$T$2:$T$500,0)),"!нет в справочнике")) -> KPI-004 | V10: % выполнения плана | W10: =IF(V10="","",IFERROR(INDEX(Справочники!$Z$2:$Z$500,MATCH(V10,Справочники!$AA$2:$AA$500,0)),"!нет в справочнике")) -> PCT | X10: % вып. плана КВ фин. услуг → коэффициент | Y10: =IF(X10="","",IFERROR(INDEX(Шкалы!$A$2:$A$500,MATCH(X10,Шкалы!$B$2:$B$500,0)),"!нет в справочнике")) -> SC-004 | Z10: 46023 | AC10: =IF(A10="","",IF(COUNTIF($A$2:$A$500,A10)>1,"Дубль код_ПОТ",IF(COUNTBLANK(B10:Z10)>0,"Не заполнены обязательные поля",IF(COUNTIF(C10:Y10,"!*")>0,"Значение не найдено в справочнике",IF(AND(AA10<>"",N(AA10)<N(Z10)),"дата_окончания раньше дата_начала",IF(COUNTIF(Шкалы_ступени!$B$2:$B$500,Y10)=0,"У шкалы нет ступеней",IF(SUMPRODUCT(($C$2:$C$500=C10)*($E$2:$E$500=E10)*($G$2:$G$500=G10)*($I$2:$I$500=I10)*($K$2:$K$500=K10)*($M$2:$M$500=M10)*(ROW($A$2:$A$500)<>ROW())*($Z$2:$Z$500<=(AA10="")*1E+99+N(AA10))*((($AA$2:$AA$500="")*1E+99+$AA$2:$AA$500)>=N(Z10)))>0,"Пересечение со строкой с тем же набором атрибутов","ОК"))))))) -> ОК

Sheet Описание_полей
A1: Лист | B1: Столбец | C1: Заполняет | D1: Обязательный | E1: Тип / формат | F1: Правило | G1: Пример | H1: В ETL
A2: ПОТ_Премии | B2: код_ПОТ | C2: Пользователь | D2: Да | E2: Текст | F2: Уникальный. Формат ПОТ-NNN. Не менять после загрузки. Не использовать повторно. | G2: ПОТ-010 | H2: Да
A3: ПОТ_Премии | B3: ДЦ | C3: Пользователь | D3: Да | E3: Текст, список | F3: Выбор из справочника ref (ДЦ). | G3: ДЦ Север | H3: Нет
A4: ПОТ_Премии | B4: код_ДЦ | C4: Авто | D4: — | E4: Текст | F4: Код из справочника. Скрытый столбец. | G4: DC-01 | H4: Да
A5: ПОТ_Премии | B5: ЦФО | C5: Пользователь | D5: Да | E5: Текст, список | F5: Выбор из справочника ref (ЦФО). | G5: Продажи новых АМ | H5: Нет
A6: ПОТ_Премии | B6: код_ЦФО | C6: Авто | D6: — | E6: Текст | F6: Код из справочника. Скрытый столбец. | G6: CFO-01 | H6: Да
A7: ПОТ_Премии | B7: подразделение | C7: Пользователь | D7: Да | E7: Текст, список | F7: Выбор из справочника ref (подразделение). | G7: Отдел продаж новых АМ | H7: Нет
A8: ПОТ_Премии | B8: код_подразделения | C8: Авто | D8: — | E8: Текст | F8: Код из справочника. Скрытый столбец. | G8: DEP-01 | H8: Да
A9: ПОТ_Премии | B9: марка | C9: Пользователь | D9: Да | E9: Текст, список | F9: Выбор из справочника ref (марка). | G9: Haval / Не определена | H9: Нет
A10: ПОТ_Премии | B10: код_марки | C10: Авто | D10: — | E10: Текст | F10: Код из справочника. Скрытый столбец. | G10: BR-01 | H10: Да
A11: ПОТ_Премии | B11: должность | C11: Пользователь | D11: Да | E11: Текст, список | F11: Выбор из справочника ref (должность). | G11: Менеджер по продажам новых АМ | H11: Нет
A12: ПОТ_Премии | B12: код_должности | C12: Авто | D12: — | E12: Текст | F12: Код из справочника. Скрытый столбец. | G12: POS-001 | H12: Да
... A45: Справочники | B45: ед_изм (ref_kpi) | C45: Хранилище | D45: Да | E45: Текст | F45: Единица измерения KPI. | G45: руб | H45: Да

Sheet Справочники
A1: Справочники. Источник — Хранилище / SAP HR. Бизнес-пользователь их не меняет. Коды — условные, заменить на коды Хранилища.
A3: код_ДЦ | B3: ДЦ | D3: код_ЦФО | E3: ЦФО | G3: код_подразделения | H3: подразделение | J3: код_марки | K3: марка | M3: код_должности | N3: должность | P3: код_вида_премии | Q3: вид_премии | S3: код_KPI | T3: KPI | U3: ед_изм | W3: код_периодичности | X3: периодичность | Z3: код_типа_значения | AA3: тип_значения | AC3: код_типа_множителя | AD3: тип_множителя
A4: DC-01 | B4: ДЦ Север | D4: CFO-01 | E4: Продажи новых АМ | G4: DEP-01 | H4: Отдел продаж новых АМ | J4: BR-00 | K4: Не определена | M4: POS-001 | N4: Менеджер по продажам новых АМ | P4: BT-001 | Q4: Премия за количество новых АМ | S4: KPI-001 | T4: Кол-во проданных новых АМ | U4: шт | W4: MONTH | X4: Ежемесячно | Z4: FACT | AA4: Факт | AC4: CONST | AD4: Число
A5: DC-02 | B5: ДЦ Юг | D5: CFO-02 | E5: Финансовые услуги | G5: DEP-02 | H5: Отдел кредитования и страхования | J5: BR-01 | K5: Haval | M5: POS-002 | N5: Мастер-консультант | P5: BT-002 | Q5: Премия за кумулятивную маржу при продаже новых АМ | S5: KPI-002 | T5: Кумулятивная маржа при продаже новых АМ | U5: руб | W5: QUARTER | X5: Ежеквартально | Z5: PLAN | AA5: План | AC5: KPI_SCALE | AD5: Значение KPI шкалы
A6: DC-03 | B6: ДЦ Запад | D6: CFO-03 | E6: Сервис | G6: DEP-03 | H6: Сервисный центр | J6: BR-02 | K6: Chery | M6: POS-003 | N6: Менеджер по кредитованию и страхованию | P6: BT-003 | Q6: Премия за маржу от продажи сервисных услуг | S6: KPI-003 | T6: Маржа от продажи сервисных услуг | U6: руб | W6: YEAR | X6: Ежегодно | Z6: PCT | AA6: % выполнения плана
J7: BR-03 | K7: Geely | P7: BT-004 | Q7: Премия за КВ от продажи финансовых услуг | S7: KPI-004 | T7: КВ от продажи финансовых услуг | U7: руб
S8: KPI-005 | T8: Премия за КВ от продажи финансовых услуг | U8: руб

Sheet Шкалы
A1: код_шкалы | B1: шкала | C1: описание
A2: SC-001 | B2: Кол-во новых АМ → сумма за 1 АМ | C2: Аргумент — кол-во проданных новых АМ, шт
A3: SC-002 | B3: Кол-во новых АМ → доля кумулятивной маржи | C3: Аргумент — кол-во проданных новых АМ, шт
A4: SC-003 | B4: % вып. плана маржи сервиса → коэффициент | C4: Аргумент — % выполнения плана
A5: SC-004 | B5: % вып. плана КВ фин. услуг → коэффициент | C5: Аргумент — % выполнения плана

Sheet Шкалы_ступени
A1: шкала | B1: код_шкалы | C1: номер_ступени | D1: значение_от | E1: значение_до | F1: тип_множителя | G1: код_типа_множителя | H1: множитель | I1: проверка
A2: Кол-во новых АМ → сумма за 1 АМ | B2: =IF(A2="","",IFERROR(INDEX(Шкалы!$A$2:$A$500,MATCH(A2,Шкалы!$B$2:$B$500,0)),"!нет в справочнике")) -> SC-001 | C2: 1 | D2: 0 | E2: 3 | F2: Число | G2: =IF(F2="","",IFERROR(INDEX(Справочники!$AC$2:$AC$500,MATCH(F2,Справочники!$AD$2:$AD$500,0)),"!нет в справочнике")) -> CONST | H2: 0 | I2: =IF(A2="","",IF(OR(B2="",LEFT(B2,1)="!"),"Шкала не найдена",IF(OR(C2="",D2="",F2=""),"Не заполнены обязательные поля",IF(AND(G2="CONST",H2=""),"Не указан множитель",IF(AND(G2="KPI_SCALE",H2<>""),"Множитель должен быть пустым",IF(COUNTIFS($B$2:$B$500,B2,$C$2:$C$500,C2)>1,"Дубль номера ступени",IF(AND(E2<>"",N(E2)<=N(D2)),"значение_до <= значение_от",IF(SUMPRODUCT(($B$2:$B$500=B2)*(ROW($B$2:$B$500)<>ROW())*($D$2:$D$500<(E2="")*1E+99+N(E2))*((($E$2:$E$500="")*1E+99+$E$2:$E$500)>D2))>0,"Пересечение диапазонов",IF(AND(E2<>"",COUNTIFS($B$2:$B$500,B2,$D$2:$D$500,E2)=0),"Разрыв после значения "&E2,"ОК"))))))))) -> ОК
A3: Кол-во новых АМ → сумма за 1 АМ | B3: =IF(A3="","",IFERROR(INDEX(Шкалы!$A$2:$A$500,MATCH(A3,Шкалы!$B$2:$B$500,0)),"!нет в справочнике")) -> SC-001 | C3: 2 | D3: 3 | E3: 6 | F3: Число | G3: =IF(F3="","",IFERROR(INDEX(Справочники!$AC$2:$AC$500,MATCH(F3,Справочники!$AD$2:$AD$500,0)),"!нет в справочнике")) -> CONST | H3: 10000 | I3: =IF(A3="","",IF(OR(B3="",LEFT(B3,1)="!"),"Шкала не найдена",IF(OR(C3="",D3="",F3=""),"Не заполнены обязательные поля",IF(AND(G3="CONST",H3=""),"Не указан множитель",IF(AND(G3="KPI_SCALE",H3<>""),"Множитель должен быть пустым",IF(COUNTIFS($B$2:$B$500,B3,$C$2:$C$500,C3)>1,"Дубль номера ступени",IF(AND(E3<>"",N(E3)<=N(D3)),"значение_до <= значение_от",IF(SUMPRODUCT(($B$2:$B$500=B3)*(ROW($B$2:$B$500)<>ROW())*($D$2:$D$500<(E3="")*1E+99+N(E3))*((($E$2:$E$500="")*1E+99+$E$2:$E$500)>D3))>0,"Пересечение диапазонов",IF(AND(E3<>"",COUNTIFS($B$2:$B$500,B3,$D$2:$D$500,E3)=0),"Разрыв после значения "&E3,"ОК"))))))))) -> ОК
A4: Кол-во новых АМ → сумма за 1 АМ | B4: =IF(A4="","",IFERROR(INDEX(Шкалы!$A$2:$A$500,MATCH(A4,Шкалы!$B$2:$B$500,0)),"!нет в справочнике")) -> SC-001 | C4: 3 | D4: 6 | E4: 15 | F4: Число | G4: =IF(F4="","",IFERROR(INDEX(Справочники!$AC$2:$AC$500,MATCH(F4,Справочники!$AD$2:$AD$500,0)),"!нет в справочнике")) -> CONST | H4: 15000 | I4: =IF(A4="","",IF(OR(B4="",LEFT(B4,1)="!"),"Шкала не найдена",IF(OR(C4="",D4="",F4=""),"Не заполнены обязательные поля",IF(AND(G4="CONST",H4=""),"Не указан множитель",IF(AND(G4="KPI_SCALE",H4<>""),"Множитель должен быть пустым",IF(COUNTIFS($B$2:$B$500,B4,$C$2:$C$500,C4)>1,"Дубль номера ступени",IF(AND(E4<>"",N(E4)<=N(D4)),"значение_до <= значение_от",IF(SUMPRODUCT(($B$2:$B$500=B4)*(ROW($B$2:$B$500)<>ROW())*($D$2:$D$500<(E4="")*1E+99+N(E4))*((($E$2:$E$500="")*1E+99+$E$2:$E$500)>D4))>0,"Пересечение диапазонов",IF(AND(E4<>"",COUNTIFS($B$2:$B$500,B4,$D$2:$D$500,E4)=0),"Разрыв после значения "&E4,"ОК"))))))))) -> ОК
A5: Кол-во новых АМ → сумма за 1 АМ | B5: =IF(A5="","",IFERROR(INDEX(Шкалы!$A$2:$A$500,MATCH(A5,Шкалы!$B$2:$B$500,0)),"!нет в справочнике")) -> SC-001 | C5: 4 | D5: 15 | F5: Число | G5: =IF(F5="","",IFERROR(INDEX(Справочники!$AC$2:$AC$500,MATCH(F5,Справочники!$AD$2:$AD$500,0)),"!нет в справочнике")) -> CONST | H5: 17000 | I5: =IF(A5="","",IF(OR(B5="",LEFT(B5,1)="!"),"Шкала не найдена",IF(OR(C5="",D5="",F5=""),"Не заполнены обязательные поля",IF(AND(G5="CONST",H5=""),"Не указан множитель",IF(AND(G5="KPI_SCALE",H5<>""),"Множитель должен быть пустым",IF(COUNTIFS($B$2:$B$500,B5,$C$2:$C$500,C5)>1,"Дубль номера ступени",IF(AND(E5<>"",N(E5)<=N(D5)),"значение_до <= значение_от",IF(SUMPRODUCT(($B$2:$B$500=B5)*(ROW($B$2:$B$500)<>ROW())*($D$2:$D$500<(E5="")*1E+99+N(E5))*((($E$2:$E$500="")*1E+99+$E$2:$E$500)>D5))>0,"Пересечение диапазонов",IF(AND(E5<>"",COUNTIFS($B$2:$B$500,B5,$D$2:$D$500,E5)=0),"Разрыв после значения "&E5,"ОК"))))))))) -> ОК
A6: Кол-во новых АМ → доля кумулятивной маржи | B6: =IF(A6="","",IFERROR(INDEX(Шкалы!$A$2:$A$500,MATCH(A6,Шкалы!$B$2:$B$500,0)),"!нет в справочнике")) -> SC-002 | C6: 1 | D6: 0 | E6: 3 | F6: Число | G6: =IF(F6="","",IFERROR(INDEX(Справочники!$AC$2:$AC$500,MATCH(F6,Справочники!$AD$2:$AD$500,0)),"!нет в справочнике")) -> CONST | H6: 0 | I6: =IF(A6="","",IF(OR(B6="",LEFT(B6,1)="!"),"Шкала не найдена",IF(OR(C6="",D6="",F6=""),"Не заполнены обязательные поля",IF(AND(G6="CONST",H6=""),"Не указан множитель",IF(AND(G6="KPI_SCALE",H6<>""),"Множитель должен быть пустым",IF(COUNTIFS($B$2:$B$500,B6,$C$2:$C$500,C6)>1,"Дубль номера ступени",IF(AND(E6<>"",N(E6)<=N(D6)),"значение_до <= значение_от",IF(SUMPRODUCT(($B$2:$B$500=B6)*(ROW($B$2:$B$500)<>ROW())*($D$2:$D$500<(E6="")*1E+99+N(E6))*((($E$2:$E$500="")*1E+99+$E$2:$E$500)>D6))>0,"Пересечение диапазонов",IF(AND(E6<>"",COUNTIFS($B$2:$B$500,B6,$D$2:$D$500,E6)=0),"Разрыв после значения "&E6,"ОК"))))))))) -> ОК
A7: Кол-во новых АМ → доля кумулятивной маржи | B7: =IF(A7="","",IFERROR(INDEX(Шкалы!$A$2:$A$500,MATCH(A7,Шкалы!$B$2:$B$500,0)),"!нет в справочнике")) -> SC-002 | C7: 2 | D7: 3 | E7: 6 | F7: Число | G7: =IF(F7="","",IFERROR(INDEX(Справочники!$AC$2:$AC$500,MATCH(F7,Справочники!$AD$2:$AD$500,0)),"!нет в справочнике")) -> CONST | H7: 0.02 | I7: =IF(A7="","",IF(OR(B7="",LEFT(B7,1)="!"),"Шкала не найдена",IF(OR(C7="",D7="",F7=""),"Не заполнены обязательные поля",IF(AND(G7="CONST",H7=""),"Не указан множитель",IF(AND(G7="KPI_SCALE",H7<>""),"Множитель должен быть пустым",IF(COUNTIFS($B$2:$B$500,B7,$C$2:$C$500,C7)>1,"Дубль номера ступени",IF(AND(E7<>"",N(E7)<=N(D7)),"значение_до <= значение_от",IF(SUMPRODUCT(($B$2:$B$500=B7)*(ROW($B$2:$B$500)<>ROW())*($D$2:$D$500<(E7="")*1E+99+N(E7))*((($E$2:$E$500="")*1E+99+$E$2:$E$500)>D7))>0,"Пересечение диапазонов",IF(AND(E7<>"",COUNTIFS($B$2:$B$500,B7,$D$2:$D$500,E7)=0),"Разрыв после значения "&E7,"ОК"))))))))) -> ОК
A8: Кол-во новых АМ → доля кумулятивной маржи | B8: =IF(A8="","",IFERROR(INDEX(Шкалы!$A$2:$A$500,MATCH(A8,Шкалы!$B$2:$B$500,0)),"!нет в справочнике")) -> SC-002 | C8: 3 | D8: 6 | E8: 15 | F8: Число | G8: =IF(F8="","",IFERROR(INDEX(Справочники!$AC$2:$AC$500,MATCH(F8,Справочники!$AD$2:$AD$500,0)),"!нет в справочнике")) -> CONST | H8: 0.04 | I8: =IF(A8="","",IF(OR(B8="",LEFT(B8,1)="!"),"Шкала не найдена",IF(OR(C8="",D8="",F8=""),"Не заполнены обязательные поля",IF(AND(G8="CONST",H8=""),"Не указан множитель",IF(AND(G8="KPI_SCALE",H8<>""),"Множитель должен быть пустым",IF(COUNTIFS($B$2:$B$500,B8,$C$2:$C$500,C8)>1,"Дубль номера ступени",IF(AND(E8<>"",N(E8)<=N(D8)),"значение_до <= значение_от",IF(SUMPRODUCT(($B$2:$B$500=B8)*(ROW($B$2:$B$500)<>ROW())*($D$2:$D$500<(E8="")*1E+99+N(E8))*((($E$2:$E$500="")*1E+99+$E$2:$E$500)>D8))>0,"Пересечение диапазонов",IF(AND(E8<>"",COUNTIFS($B$2:$B$500,B8,$D$2:$D$500,E8)=0),"Разрыв после значения "&E8,"ОК"))))))))) -> ОК
A9: Кол-во новых АМ → доля кумулятивной маржи | B9: =IF(A9="","",IFERROR(INDEX(Шкалы!$A$2:$A$500,MATCH(A9,Шкалы!$B$2:$B$500,0)),"!нет в справочнике")) -> SC-002 | C9: 4 | D9: 15 | F9: Число | G9: =IF(F9="","",IFERROR(INDEX(Справочники!$AC$2:$AC$500,MATCH(F9,Справочники!$AD$2:$AD$500,0)),"!нет в справочнике")) -> CONST | H9: 0.05 | I9: =IF(A9="","",IF(OR(B9="",LEFT(B9,1)="!"),"Шкала не найдена",IF(OR(C9="",D9="",F9=""),"Не заполнены обязательные поля",IF(AND(G9="CONST",H9=""),"Не указан множитель",IF(AND(G9="KPI_SCALE",H9<>""),"Множитель должен быть пустым",IF(COUNTIFS($B$2:$B$500,B9,$C$2:$C$500,C9)>1,"Дубль номера ступени",IF(AND(E9<>"",N(E9)<=N(D9)),"значение_до <= значение_от",IF(SUMPRODUCT(($B$2:$B$500=B9)*(ROW($B$2:$B$500)<>ROW())*($D$2:$D$500<(E9="")*1E+99+N(E9))*((($E$2:$E$500="")*1E+99+$E$2:$E$500)>D9))>0,"Пересечение диапазонов",IF(AND(E9<>"",COUNTIFS($B$2:$B$500,B9,$D$2:$D$500,E9)=0),"Разрыв после значения "&E9,"ОК"))))))))) -> ОК
A10: % вып. плана маржи сервиса → коэффициент | B10: =IF(A10="","",IFERROR(INDEX(Шкалы!$A$2:$A$500,MATCH(A10,Шкалы!$B$2:$B$500,0)),"!нет в справочнике")) -> SC-003 | C10: 1 | D10: 0 | E10: 0.8 | F10: Число | G10: =IF(F10="","",IFERROR(INDEX(Справочники!$AC$2:$AC$500,MATCH(F10,Справочники!$AD$2:$AD$500,0)),"!нет в справочнике")) -> CONST | H10: 0 | I10: =IF(A10="","",IF(OR(B10="",LEFT(B10,1)="!"),"Шкала не найдена",IF(OR(C10="",D10="",F10=""),"Не заполнены обязательные поля",IF(AND(G10="CONST",H10=""),"Не указан множитель",IF(AND(G10="KPI_SCALE",H10<>""),"Множитель должен быть пустым",IF(COUNTIFS($B$2:$B$500,B10,$C$2:$C$500,C10)>1,"Дубль номера ступени",IF(AND(E10<>"",N(E10)<=N(D10)),"значение_до <= значение_от",IF(SUMPRODUCT(($B$2:$B$500=B10)*(ROW($B$2:$B$500)<>ROW())*($D$2:$D$500<(E10="")*1E+99+N(E10))*((($E$2:$E$500="")*1E+99+$E$2:$E$500)>D10))>0,"Пересечение диапазонов",IF(AND(E10<>"",COUNTIFS($B$2:$B$500,B10,$D$2:$D$500,E10)=0),"Разрыв после значения "&E10,"ОК"))))))))) -> ОК
A11: % вып. плана маржи сервиса → коэффициент | B11: =IF(A11="","",IFERROR(INDEX(Шкалы!$A$2:$A$500,MATCH(A11,Шкалы!$B$2:$B$500,0)),"!нет в справочнике")) -> SC-003 | C11: 2 | D11: 0.8 | E11: 1.2 | F11: Значение KPI шкалы | G11: =IF(F11="","",IFERROR(INDEX(Справочники!$AC$2:$AC$500,MATCH(F11,Справочники!$AD$2:$AD$500,0)),"!нет в справочнике")) -> KPI_SCALE | I11: =IF(A11="","",IF(OR(B11="",LEFT(B11,1)="!"),"Шкала не найдена",IF(OR(C11="",D11="",F11=""),"Не заполнены обязательные поля",IF(AND(G11="CONST",H11=""),"Не указан множитель",IF(AND(G11="KPI_SCALE",H11<>""),"Множитель должен быть пустым",IF(COUNTIFS($B$2:$B$500,B11,$C$2:$C$500,C11)>1,"Дубль номера ступени",IF(AND(E11<>"",N(E11)<=N(D11)),"значение_до <= значение_от",IF(SUMPRODUCT(($B$2:$B$500=B11)*(ROW($B$2:$B$500)<>ROW())*($D$2:$D$500<(E11="")*1E+99+N(E11))*((($E$2:$E$500="")*1E+99+$E$2:$E$500)>D11))>0,"Пересечение диапазонов",IF(AND(E11<>"",COUNTIFS($B$2:$B$500,B11,$D$2:$D$500,E11)=0),"Разрыв после значения "&E11,"ОК"))))))))) -> ОК
A12: % вып. плана маржи сервиса → коэффициент | B12: =IF(A12="","",IFERROR(INDEX(Шкалы!$A$2:$A$500,MATCH(A12,Шкалы!$B$2:$B$500,0)),"!нет в справочнике")) -> SC-003 | C12: 3 | D12: 1.2 | F12: Число | G12: =IF(F12="","",IFERROR(INDEX(Справочники!$AC$2:$AC$500,MATCH(F12,Справочники!$AD$2:$AD$500,0)),"!нет в справочнике")) -> CONST | H12: 1.2 | I12: =IF(A12="","",IF(OR(B12="",LEFT(B12,1)="!"),"Шкала не найдена",IF(OR(C12="",D12="",F12=""),"Не заполнены обязательные поля",IF(AND(G12="CONST",H12=""),"Не указан множитель",IF(AND(G12="KPI_SCALE",H12<>""),"Множитель должен быть пустым",IF(COUNTIFS($B$2:$B$500,B12,$C$2:$C$500,C12)>1,"Дубль номера ступени",IF(AND(E12<>"",N(E12)<=N(D12)),"значение_до <= значение_от",IF(SUMPRODUCT(($B$2:$B$500=B12)*(ROW($B$2:$B$500)<>ROW())*($D$2:$D$500<(E12="")*1E+99+N(E12))*((($E$2:$E$500="")*1E+99+$E$2:$E$500)>D12))>0,"Пересечение диапазонов",IF(AND(E12<>"",COUNTIFS($B$2:$B$500,B12,$D$2:$D$500,E12)=0),"Разрыв после значения "&E12,"ОК"))))))))) -> ОК
A13: % вып. плана КВ фин. услуг → коэффициент | B13: =IF(A13="","",IFERROR(INDEX(Шкалы!$A$2:$A$500,MATCH(A13,Шкалы!$B$2:$B$500,0)),"!нет в справочнике")) -> SC-004 | C13: 1 | D13: 0 | E13: 0.8 | F13: Число | G13: =IF(F13="","",IFERROR(INDEX(Справочники!$AC$2:$AC$500,MATCH(F13,Справочники!$AD$2:$AD$500,0)),"!нет в справочнике")) -> CONST | H13: 0.5 | I13: =IF(A13="","",IF(OR(B13="",LEFT(B13,1)="!"),"Шкала не найдена",IF(OR(C13="",D13="",F13=""),"Не заполнены обязательные поля",IF(AND(G13="CONST",H13=""),"Не указан множитель",IF(AND(G13="KPI_SCALE",H13<>""),"Множитель должен быть пустым",IF(COUNTIFS($B$2:$B$500,B13,$C$2:$C$500,C13)>1,"Дубль номера ступени",IF(AND(E13<>"",N(E13)<=N(D13)),"значение_до <= значение_от",IF(SUMPRODUCT(($B$2:$B$500=B13)*(ROW($B$2:$B$500)<>ROW())*($D$2:$D$500<(E13="")*1E+99+N(E13))*((($E$2:$E$500="")*1E+99+$E$2:$E$500)>D13))>0,"Пересечение диапазонов",IF(AND(E13<>"",COUNTIFS($B$2:$B$500,B13,$D$2:$D$500,E13)=0),"Разрыв после значения "&E13,"ОК"))))))))) -> ОК
A14: % вып. плана КВ фин. услуг → коэффициент | B14: =IF(A14="","",IFERROR(INDEX(Шкалы!$A$2:$A$500,MATCH(A14,Шкалы!$B$2:$B$500,0)),"!нет в справочнике")) -> SC-004 | C14: 2 | D14: 0.8 | E14: 1.2 | F14: Значение KPI шкалы | G14: =IF(F14="","",IFERROR(INDEX(Справочники!$AC$2:$AC$500,MATCH(F14,Справочники!$AD$2:$AD$500,0)),"!нет в справочнике")) -> KPI_SCALE | I14: =IF(A14="","",IF(OR(B14="",LEFT(B14,1)="!"),"Шкала не найдена",IF(OR(C14="",D14="",F14=""),"Не заполнены обязательные поля",IF(AND(G14="CONST",H14=""),"Не указан множитель",IF(AND(G14="KPI_SCALE",H14<>""),"Множитель должен быть пустым",IF(COUNTIFS($B$2:$B$500,B14,$C$2:$C$500,C14)>1,"Дубль номера ступени",IF(AND(E14<>"",N(E14)<=N(D14)),"значение_до <= значение_от",IF(SUMPRODUCT(($B$2:$B$500=B14)*(ROW($B$2:$B$500)<>ROW())*($D$2:$D$500<(E14="")*1E+99+N(E14))*((($E$2:$E$500="")*1E+99+$E$2:$E$500)>D14))>0,"Пересечение диапазонов",IF(AND(E14<>"",COUNTIFS($B$2:$B$500,B14,$D$2:$D$500,E14)=0),"Разрыв после значения "&E14,"ОК"))))))))) -> ОК
A15: % вып. плана КВ фин. услуг → коэффициент | B15: =IF(A15="","",IFERROR(INDEX(Шкалы!$A$2:$A$500,MATCH(A15,Шкалы!$B$2:$B$500,0)),"!нет в справочнике")) -> SC-004 | C15: 3 | D15: 1.2 | F15: Число | G15: =IF(F15="","",IFERROR(INDEX(Справочники!$AC$2:$AC$500,MATCH(F15,Справочники!$AD$2:$AD$500,0)),"!нет в справочнике")) -> CONST | H15: 1.2 | I15: =IF(A15="","",IF(OR(B15="",LEFT(B15,1)="!"),"Шкала не найдена",IF(OR(C15="",D15="",F15=""),"Не заполнены обязательные поля",IF(AND(G15="CONST",H15=""),"Не указан множитель",IF(AND(G15="KPI_SCALE",H15<>""),"Множитель должен быть пустым",IF(COUNTIFS($B$2:$B$500,B15,$C$2:$C$500,C15)>1,"Дубль номера ступени",IF(AND(E15<>"",N(E15)<=N(D15)),"значение_до <= значение_от",IF(SUMPRODUCT(($B$2:$B$500=B15)*(ROW($B$2:$B$500)<>ROW())*($D$2:$D$500<(E15="")*1E+99+N(E15))*((($E$2:$E$500="")*1E+99+$E$2:$E$500)>D15))>0,"Пересечение диапазонов",IF(AND(E15<>"",COUNTIFS($B$2:$B$500,B15,$D$2:$D$500,E15)=0),"Разрыв после значения "&E15,"ОК"))))))))) -> ОК

Sheet Проверки
A1: Проверка перед передачей файла в ETL
A3: Таблица | B3: Строк | C3: Ошибок
A4: ПОТ_Премии | B4: =COUNTA(ПОТ_Премии!A2:A500) -> 9 | C4: =COUNTIFS(ПОТ_Премии!A2:A500,"<>",ПОТ_Премии!AC2:AC500,"<>ОК") -> 0
A5: Шкалы_ступени | B5: =COUNTA(Шкалы_ступени!A2:A500) -> 14 | C5: =COUNTIFS(Шкалы_ступени!A2:A500,"<>",Шкалы_ступени!I2:I500,"<>ОК") -> 0
A6: Шкалы без ПОТ | B6: =COUNTA(Шкалы!A2:A500) -> 4 | C6: =SUMPRODUCT((Шкалы!A2:A500<>"")*(COUNTIF(ПОТ_Премии!Y2:Y500,Шкалы!A2:A500)=0)) -> 0
A8: Файл готов к загрузке | B8: =IF(C4+C5=0,"ДА","НЕТ — исправьте строки со статусом, отличным от ОК") -> ДА
A9: «Шкалы без ПОТ» — предупреждение, загрузку не блокирует.

Sheet Пример_расчёта
A1: Пример расчёта премии по сотрудникам. НЕ источник ETL — показывает, как Хранилище применит ПОТ к значениям KPI. Желтые ячейки — значения KPI (в Хранилище они берутся из фактов KPI).
A3: период | B3: фио_сотрудника | C3: ДЦ | D3: ЦФО | E3: подразделение | F3: марка | G3: должность | H3: вид_премии | I3: значение_KPI_расчёта | J3: значение_KPI_шкалы | K3: код_ПОТ | L3: код_шкалы | M3: номер_ступени | N3: множитель | O3: премия_руб
A4: 2026-09 | B4: Иванов Алексей Петрович | C4: ДЦ Север | D4: Продажи новых АМ | E4: Отдел продаж новых АМ | F4: Haval | G4: Менеджер по продажам новых АМ | H4: Премия за количество новых АМ | I4: 10 | J4: 10 | K4: =IFERROR(INDEX(ПОТ_Премии!$A$2:$A$500,MATCH(1,INDEX((ПОТ_Премии!$B$2:$B$500=C4)*(ПОТ_Премии!$D$2:$D$500=D4)*(ПОТ_Премии!$F$2:$F$500=E4)*(ПОТ_Премии!$H$2:$H$500=F4)*(ПОТ_Премии!$J$2:$J$500=G4)*(ПОТ_Премии!$L$2:$L$500=H4),0),0)),"ПОТ не найден") -> ПОТ-001 | L4: =IFERROR(INDEX(ПОТ_Премии!$Y$2:$Y$500,MATCH(K4,ПОТ_Премии!$A$2:$A$500,0)),"") -> SC-001 | M4: =IF(L4="","",SUMIFS(Шкалы_ступени!$C$2:$C$500,Шкалы_ступени!$B$2:$B$500,L4,Шкалы_ступени!$D$2:$D$500,"<="&J4,Шкалы_ступени!$E$2:$E$500,">"&J4)+SUMIFS(Шкалы_ступени!$C$2:$C$500,Шкалы_ступени!$B$2:$B$500,L4,Шкалы_ступени!$D$2:$D$500,"<="&J4,Шкалы_ступени!$E$2:$E$500,"=")) -> 3 | N4: =IF(OR(L4="",M4=0),"",IF(INDEX(Шкалы_ступени!$G$2:$G$500,MATCH(1,INDEX((Шкалы_ступени!$B$2:$B$500=L4)*(Шкалы_ступени!$C$2:$C$500=M4),0),0))="KPI_SCALE",J4,INDEX(Шкалы_ступени!$H$2:$H$500,MATCH(1,INDEX((Шкалы_ступени!$B$2:$B$500=L4)*(Шкалы_ступени!$C$2:$C$500=M4),0),0)))) -> 15000 | O4: =IF(N4="","",ROUND(I4*N4,2)) -> 150000
A5: 2026-10 | B5: Иванов Алексей Петрович | C5: ДЦ Север | D5: Продажи новых АМ | E5: Отдел продаж новых АМ | F5: Haval | G5: Менеджер по продажам новых АМ | H5: Премия за кумулятивную маржу при продаже новых АМ | I5: 12000000 | J5: 12 | K5: =IFERROR(INDEX(ПОТ_Премии!$A$2:$A$500,MATCH(1,INDEX((ПОТ_Премии!$B$2:$B$500=C5)*(ПОТ_Премии!$D$2:$D$500=D5)*(ПОТ_Премии!$F$2:$F$500=E5)*(ПОТ_Премии!$H$2:$H$500=F5)*(ПОТ_Премии!$J$2:$J$500=G5)*(ПОТ_Премии!$L$2:$L$500=H5),0),0)),"ПОТ не найден") -> ПОТ-002 | L5: =IFERROR(INDEX(ПОТ_Премии!$Y$2:$Y$500,MATCH(K5,ПОТ_Премии!$A$2:$A$500,0)),"") -> SC-002 | M5: =IF(L5="","",SUMIFS(Шкалы_ступени!$C$2:$C$500,Шкалы_ступени!$B$2:$B$500,L5,Шкалы_ступени!$D$2:$D$500,"<="&J5,Шкалы_ступени!$E$2:$E$500,">"&J5)+SUMIFS(Шкалы_ступени!$C$2:$C$500,Шкалы_ступени!$B$2:$B$500,L5,Шкалы_ступени!$D$2:$D$500,"<="&J5,Шкалы_ступени!$E$2:$E$500,"=")) -> 3 | N5: =IF(OR(L5="",M5=0),"",IF(INDEX(Шкалы_ступени!$G$2:$G$500,MATCH(1,INDEX((Шкалы_ступени!$B$2:$B$500=L5)*(Шкалы_ступени!$C$2:$C$500=M5),0),0))="KPI_SCALE",J5,INDEX(Шкалы_ступени!$H$2:$H$500,MATCH(1,INDEX((Шкалы_ступени!$B$2:$B$500=L5)*(Шкалы_ступени!$C$2:$C$500=M5),0),0)))) -> 0.04 | O5: =IF(N5="","",ROUND(I5*N5,2)) -> 480000
A6: 2026-11 | B6: Смирнова Елена Сергеевна | C6: ДЦ Север | D6: Продажи новых АМ | E6: Отдел продаж новых АМ | F6: Chery | G6: Менеджер по продажам новых АМ | H6: Премия за количество новых АМ | I6: 30 | J6: 30 | K6: =IFERROR(INDEX(ПОТ_Премии!$A$2:$A$500,MATCH(1,INDEX((ПОТ_Премии!$B$2:$B$500=C6)*(ПОТ_Премии!$D$2:$D$500=D6)*(ПОТ_Премии!$F$2:$F$500=E6)*(ПОТ_Премии!$H$2:$H$500=F6)*(ПОТ_Премии!$J$2:$J$500=G6)*(ПОТ_Премии!$L$2:$L$500=H6),0),0)),"ПОТ не найден") -> ПОТ-003 | L6: =IFERROR(INDEX(ПОТ_Премии!$Y$2:$Y$500,MATCH(K6,ПОТ_Премии!$A$2:$A$500,0)),"") -> SC-001 | M6: =IF(L6="","",SUMIFS(Шкалы_ступени!$C$2:$C$500,Шкалы_ступени!$B$2:$B$500,L6,Шкалы_ступени!$D$2:$D$500,"<="&J6,Шкалы_ступени!$E$2:$E$500,">"&J6)+SUMIFS(Шкалы_ступени!$C$2:$C$500,Шкалы_ступени!$B$2:$B$500,L6,Шкалы_ступени!$D$2:$D$500,"<="&J6,Шкалы_ступени!$E$2:$E$500,"=")) -> 4 | N6: =IF(OR(L6="",M6=0),"",IF(INDEX(Шкалы_ступени!$G$2:$G$500,MATCH(1,INDEX((Шкалы_ступени!$B$2:$B$500=L6)*(Шкалы_ступени!$C$2:$C$500=M6),0),0))="KPI_SCALE",J6,INDEX(Шкалы_ступени!$H$2:$H$500,MATCH(1,INDEX((Шкалы_ступени!$B$2:$B$500=L6)*(Шкалы_ступени!$C$2:$C$500=M6),0),0)))) -> 17000 | O6: =IF(N6="","",ROUND(I6*N6,2)) -> 510000
A7: 2026-12 | B7: Морозова Анна Павловна | C7: ДЦ Юг | D7: Сервис | E7: Сервисный центр | F7: Не определена | G7: Мастер-консультант | H7: Премия за маржу от продажи сервисных услуг | I7: 800000 | J7: 1.4 | K7: =IFERROR(INDEX(ПОТ_Премии!$A$2:$A$500,MATCH(1,INDEX((ПОТ_Премии!$B$2:$B$500=C7)*(ПОТ_Премии!$D$2:$D$500=D7)*(ПОТ_Премии!$F$2:$F$500=E7)*(ПОТ_Премии!$H$2:$H$500=F7)*(ПОТ_Премии!$J$2:$J$500=G7)*(ПОТ_Премии!$L$2:$L$500=H7),0),0)),"ПОТ не найден") -> ПОТ-007 | L7: =IFERROR(INDEX(ПОТ_Премии!$Y$2:$Y$500,MATCH(K7,ПОТ_Премии!$A$2:$A$500,0)),"") -> SC-003 | M7: =IF(L7="","",SUMIFS(Шкалы_ступени!$C$2:$C$500,Шкалы_ступени!$B$2:$B$500,L7,Шкалы_ступени!$D$2:$D$500,"<="&J7,Шкалы_ступени!$E$2:$E$500,">"&J7)+SUMIFS(Шкалы_ступени!$C$2:$C$500,Шкалы_ступени!$B$2:$B$500,L7,Шкалы_ступени!$D$2:$D$500,"<="&J7,Шкалы_ступени!$E$2:$E$500,"=")) -> 3 | N7: =IF(OR(L7="",M7=0),"",IF(INDEX(Шкалы_ступени!$G$2:$G$500,MATCH(1,INDEX((Шкалы_ступени!$B$2:$B$500=L7)*(Шкалы_ступени!$C$2:$C$500=M7),0),0))="KPI_SCALE",J7,INDEX(Шкалы_ступени!$H$2:$H$500,MATCH(1,INDEX((Шкалы_ступени!$B$2:$B$500=L7)*(Шкалы_ступени!$C$2:$C$500=M7),0),0)))) -> 1.2 | O7: =IF(N7="","",ROUND(I7*N7,2)) -> 960000
A8: 2026-Q3 | B8: Петров Игорь Владимирович | C8: ДЦ Север | D8: Финансовые услуги | E8: Отдел кредитования и страхования | F8: Не определена | G8: Менеджер по кредитованию и страхованию | H8: Премия за КВ от продажи финансовых услуг | I8: 50000 | J8: 1 | K8: =IFERROR(INDEX(ПОТ_Премии!$A$2:$A$500,MATCH(1,INDEX((ПОТ_Премии!$B$2:$B$500=C8)*(ПОТ_Премии!$D$2:$D$500=D8)*(ПОТ_Премии!$F$2:$F$500=E8)*(ПОТ_Премии!$H$2:$H$500=F8)*(ПОТ_Премии!$J$2:$J$500=G8)*(ПОТ_Премии!$L$2:$L$500=H8),0),0)),"ПОТ не найден") -> ПОТ-008 | L8: =IFERROR(INDEX(ПОТ_Премии!$Y$2:$Y$500,MATCH(K8,ПОТ_Премии!$A$2:$A$500,0)),"") -> SC-004 | M8: =IF(L8="","",SUMIFS(Шкалы_ступени!$C$2:$C$500,Шкалы_ступени!$B$2:$B$500,L8,Шкалы_ступени!$D$2:$D$500,"<="&J8,Шкалы_ступени!$E$2:$E$500,">"&J8)+SUMIFS(Шкалы_ступени!$C$2:$C$500,Шкалы_ступени!$B$2:$B$500,L8,Шкалы_ступени!$D$2:$D$500,"<="&J8,Шкалы_ступени!$E$2:$E$500,"=")) -> 2 | N8: =IF(OR(L8="",M8=0),"",IF(INDEX(Шкалы_ступени!$G$2:$G$500,MATCH(1,INDEX((Шкалы_ступени!$B$2:$B$500=L8)*(Шкалы_ступени!$C$2:$C$500=M8),0),0))="KPI_SCALE",J8,INDEX(Шкалы_ступени!$H$2:$H$500,MATCH(1,INDEX((Шкалы_ступени!$B$2:$B$500=L8)*(Шкалы_ступени!$C$2:$C$500=M8),0),0)))) -> 1 | O8: =IF(N8="","",ROUND(I8*N8,2)) -> 50000
A9: 2026-Q3 | B9: Петров Игорь Владимирович | C9: ДЦ Север | D9: Финансовые услуги | E9: Отдел кредитования и страхования | F9: Не определена | G9: Менеджер по кредитованию и страхованию | H9: Премия за КВ от продажи финансовых услуг | I9: 50000 | J9: 1.2 | K9: =IFERROR(INDEX(ПОТ_Премии!$A$2:$A$500,MATCH(1,INDEX((ПОТ_Премии!$B$2:$B$500=C9)*(ПОТ_Премии!$D$2:$D$500=D9)*(ПОТ_Премии!$F$2:$F$500=E9)*(ПОТ_Премии!$H$2:$H$500=F9)*(ПОТ_Премии!$J$2:$J$500=G9)*(ПОТ_Премии!$L$2:$L$500=H9),0),0)),"ПОТ не найден") -> ПОТ-008 | L9: =IFERROR(INDEX(ПОТ_Премии!$Y$2:$Y$500,MATCH(K9,ПОТ_Премии!$A$2:$A$500,0)),"") -> SC-004 | M9: =IF(L9="","",SUMIFS(Шкалы_ступени!$C$2:$C$500,Шкалы_ступени!$B$2:$B$500,L9,Шкалы_ступени!$D$2:$D$500,"<="&J9,Шкалы_ступени!$E$2:$E$500,">"&J9)+SUMIFS(Шкалы_ступени!$C$2:$C$500,Шкалы_ступени!$B$2:$B$500,L9,Шкалы_ступени!$D$2:$D$500,"<="&J9,Шкалы_ступени!$E$2:$E$500,"=")) -> 3 | N9: =IF(OR(L9="",M9=0),"",IF(INDEX(Шкалы_ступени!$G$2:$G$500,MATCH(1,INDEX((Шкалы_ступени!$B$2:$B$500=L9)*(Шкалы_ступени!$C$2:$C$500=M9),0),0))="KPI_SCALE",J9,INDEX(Шкалы_ступени!$H$2:$H$500,MATCH(1,INDEX((Шкалы_ступени!$B$2:$B$500=L9)*(Шкалы_ступени!$C$2:$C$500=M9),0),0)))) -> 1.2 | O9: =IF(N9="","",ROUND(I9*N9,2)) -> 60000
A10: 2026-Q3 | B10: Лебедев Константин Юрьевич | C10: ДЦ Запад | D10: Финансовые услуги | E10: Отдел кредитования и страхования | F10: Не определена | G10: Менеджер по кредитованию и страхованию | H10: Премия за КВ от продажи финансовых услуг | I10: 50000 | J10: 0.76 | K10: =IFERROR(INDEX(ПОТ_Премии!$A$2:$A$500,MATCH(1,INDEX((ПОТ_Премии!$B$2:$B$500=C10)*(ПОТ_Премии!$D$2:$D$500=D10)*(ПОТ_Премии!$F$2:$F$500=E10)*(ПОТ_Премии!$H$2:$H$500=F10)*(ПОТ_Премии!$J$2:$J$500=G10)*(ПОТ_Премии!$L$2:$L$500=H10),0),0)),"ПОТ не найден") -> ПОТ-009 | L10: =IFERROR(INDEX(ПОТ_Премии!$Y$2:$Y$500,MATCH(K10,ПОТ_Премии!$A$2:$A$500,0)),"") -> SC-004 | M10: =IF(L10="","",SUMIFS(Шкалы_ступени!$C$2:$C$500,Шкалы_ступени!$B$2:$B$500,L10,Шкалы_ступени!$D$2:$D$500,"<="&J10,Шкалы_ступени!$E$2:$E$500,">"&J10)+SUMIFS(Шкалы_ступени!$C$2:$C$500,Шкалы_ступени!$B$2:$B$500,L10,Шкалы_ступени!$D$2:$D$500,"<="&J10,Шкалы_ступени!$E$2:$E$500,"=")) -> 1 | N10: =IF(OR(L10="",M10=0),"",IF(INDEX(Шкалы_ступени!$G$2:$G$500,MATCH(1,INDEX((Шкалы_ступени!$B$2:$B$500=L10)*(Шкалы_ступени!$C$2:$C$500=M10),0),0))="KPI_SCALE",J10,INDEX(Шкалы_ступени!$H$2:$H$500,MATCH(1,INDEX((Шкалы_ступени!$B$2:$B$500=L10)*(Шкалы_ступени!$C$2:$C$500=M10),0),0)))) -> 0.5 | O10: =IF(N10="","",ROUND(I10*N10,2)) -> 25000
