Workbook

Sheet ПОТ
A1: период | B1: фио_сотрудника | C1: таб_номер | D1: ДЦ | E1: ЦФО | F1: подразделение | G1: должность | H1: марка | I1: вид_премии | J1: вх_параметр_1_название | K1: ед_изм_1 | L1: вх_параметр_1_значение | M1: KPI_название | N1: KPI_ед.изм. | O1: KPI_значение | P1: тип_периода | Q1: Премия_руб | R1: лист_шкалы
A2: 46266 | B2: Иванов Алексей Петрович | C2: =IF(ISBLANK(B2),"",IFERROR(_xlfn.XLOOKUP(B2,Справ_Сотрудников!$B:$B,Справ_Сотрудников!$A:$A),"")) -> 10001 | D2: =IF(ISBLANK(B2),"",IFERROR(_xlfn.XLOOKUP(B2,Справ_Сотрудников!$B:$B,Справ_Сотрудников!$C:$C),"")) -> ДЦ Север | E2: =IF(ISBLANK(B2),"",IFERROR(_xlfn.XLOOKUP(B2,Справ_Сотрудников!$B:$B,Справ_Сотрудников!$D:$D),"")) -> Продажи новых АМ | F2: =IF(ISBLANK(B2),"",IFERROR(_xlfn.XLOOKUP(B2,Справ_Сотрудников!$B:$B,Справ_Сотрудников!$E:$E),"")) -> Отдел продаж новых АМ | G2: =IF(ISBLANK(B2),"",IFERROR(_xlfn.XLOOKUP(B2,Справ_Сотрудников!$B:$B,Справ_Сотрудников!$F:$F),"")) -> Менеджер по продажам новых АМ | H2: =IF(ISBLANK(B2),"",IFERROR(_xlfn.XLOOKUP(B2,Справ_Сотрудников!$B:$B,Справ_Сотрудников!$G:$G),"")) -> Haval | I2: Премия за количество новых АМ | J2: =IF(ISBLANK(I2),"",IFERROR(_xlfn.XLOOKUP(I2,Справ_ВидыПремий!$B:$B,Справ_ВидыПремий!$E:$E)&"","")) -> Кол-во проданных автомобилей | K2: =IF(ISBLANK(I2),"",IFERROR(_xlfn.XLOOKUP(I2,Справ_ВидыПремий!$B:$B,Справ_ВидыПремий!$F:$F)&"","")) -> ед. | L2: 10 | M2: =IF(ISBLANK(I2),"",IFERROR(_xlfn.XLOOKUP(I2,Справ_ВидыПремий!$B:$B,Справ_ВидыПремий!$G:$G)&"","")) | N2: =IF(ISBLANK(I2),"",IFERROR(_xlfn.XLOOKUP(I2,Справ_ВидыПремий!$B:$B,Справ_ВидыПремий!$H:$H)&"","")) | P2: =IF(ISBLANK(A2),"",IFERROR(_xlfn.XLOOKUP(A2,Периоды!$A:$A,Периоды!$B:$B),"")) -> ЕЖЕМЕСЯЧНО | Q2: =IF(OR(ISBLANK(I2),R2="",ISBLANK(L2)),"",ROUND(IF(IFERROR(_xlfn.XLOOKUP(L2,INDIRECT("'"&R2&"'!$C:$C"),INDIRECT("'"&R2&"'!$G:$G"),"",-1),"")="% выполнения",L2/100,IFERROR(_xlfn.XLOOKUP(L2,INDIRECT("'"&R2&"'!$C:$C"),INDIRECT("'"&R2&"'!$E:$E"),0,-1),0))*IF(ISBLANK(O2),L2,O2)+IFERROR(_xlfn.XLOOKUP(L2,INDIRECT("'"&R2&"'!$C:$C"),INDIRECT("'"&R2&"'!$F:$F"),0,-1),0),2)) -> 150000 | R2: =IF(ISBLANK(I2),"",IFERROR(_xlfn.XLOOKUP(I2,Справ_ВидыПремий!$B:$B,Справ_ВидыПремий!$I:$I),"")) -> BT-001_Премия_КолвоАМ
A3: Q3 2026 | B3: Петров Игорь Владимирович | C3: =IF(ISBLANK(B3),"",IFERROR(_xlfn.XLOOKUP(B3,Справ_Сотрудников!$B:$B,Справ_Сотрудников!$A:$A),"")) -> 10003 | D3: =IF(ISBLANK(B3),"",IFERROR(_xlfn.XLOOKUP(B3,Справ_Сотрудников!$B:$B,Справ_Сотрудников!$C:$C),"")) -> ДЦ Север | E3: =IF(ISBLANK(B3),"",IFERROR(_xlfn.XLOOKUP(B3,Справ_Сотрудников!$B:$B,Справ_Сотрудников!$D:$D),"")) -> Финансовые услуги | F3: =IF(ISBLANK(B3),"",IFERROR(_xlfn.XLOOKUP(B3,Справ_Сотрудников!$B:$B,Справ_Сотрудников!$E:$E),"")) -> Отдел кредитования и страхования | G3: =IF(ISBLANK(B3),"",IFERROR(_xlfn.XLOOKUP(B3,Справ_Сотрудников!$B:$B,Справ_Сотрудников!$F:$F),"")) -> Менеджер по кредитованию и страхованию | H3: =IF(ISBLANK(B3),"",IFERROR(_xlfn.XLOOKUP(B3,Справ_Сотрудников!$B:$B,Справ_Сотрудников!$G:$G),"")) -> ЛюбаяМарка | I3: Поквартальная премия от продажи финансовых услуг | J3: =IF(ISBLANK(I3),"",IFERROR(_xlfn.XLOOKUP(I3,Справ_ВидыПремий!$B:$B,Справ_ВидыПремий!$E:$E)&"","")) -> % выполнения плана | K3: =IF(ISBLANK(I3),"",IFERROR(_xlfn.XLOOKUP(I3,Справ_ВидыПремий!$B:$B,Справ_ВидыПремий!$F:$F)&"","")) -> % | L3: 100 | M3: =IF(ISBLANK(I3),"",IFERROR(_xlfn.XLOOKUP(I3,Справ_ВидыПремий!$B:$B,Справ_ВидыПремий!$G:$G)&"","")) -> Плановое значение премии за КВ от продажи финансовых услуг | N3: =IF(ISBLANK(I3),"",IFERROR(_xlfn.XLOOKUP(I3,Справ_ВидыПремий!$B:$B,Справ_ВидыПремий!$H:$H)&"","")) -> руб. | O3: 50000 | P3: =IF(ISBLANK(A3),"",IFERROR(_xlfn.XLOOKUP(A3,Периоды!$A:$A,Периоды!$B:$B),"")) -> ЕЖЕКВАРТАЛЬНО | Q3: =IF(OR(ISBLANK(I3),R3="",ISBLANK(L3)),"",ROUND(IF(IFERROR(_xlfn.XLOOKUP(L3,INDIRECT("'"&R3&"'!$C:$C"),INDIRECT("'"&R3&"'!$G:$G"),"",-1),"")="% выполнения",L3/100,IFERROR(_xlfn.XLOOKUP(L3,INDIRECT("'"&R3&"'!$C:$C"),INDIRECT("'"&R3&"'!$E:$E"),0,-1),0))*IF(ISBLANK(O3),L3,O3)+IFERROR(_xlfn.XLOOKUP(L3,INDIRECT("'"&R3&"'!$C:$C"),INDIRECT("'"&R3&"'!$F:$F"),0,-1),0),2)) -> 50000 | R3: =IF(ISBLANK(I3),"",IFERROR(_xlfn.XLOOKUP(I3,Справ_ВидыПремий!$B:$B,Справ_ВидыПремий!$I:$I),"")) -> BT-004_Премия_КВФин
A4: Q3 2026 | B4: Петров Игорь Владимирович | C4: =IF(ISBLANK(B4),"",IFERROR(_xlfn.XLOOKUP(B4,Справ_Сотрудников!$B:$B,Справ_Сотрудников!$A:$A),"")) -> 10003 | D4: =IF(ISBLANK(B4),"",IFERROR(_xlfn.XLOOKUP(B4,Справ_Сотрудников!$B:$B,Справ_Сотрудников!$C:$C),"")) -> ДЦ Север | E4: =IF(ISBLANK(B4),"",IFERROR(_xlfn.XLOOKUP(B4,Справ_Сотрудников!$B:$B,Справ_Сотрудников!$D:$D),"")) -> Финансовые услуги | F4: =IF(ISBLANK(B4),"",IFERROR(_xlfn.XLOOKUP(B4,Справ_Сотрудников!$B:$B,Справ_Сотрудников!$E:$E),"")) -> Отдел кредитования и страхования | G4: =IF(ISBLANK(B4),"",IFERROR(_xlfn.XLOOKUP(B4,Справ_Сотрудников!$B:$B,Справ_Сотрудников!$F:$F),"")) -> Менеджер по кредитованию и страхованию | H4: =IF(ISBLANK(B4),"",IFERROR(_xlfn.XLOOKUP(B4,Справ_Сотрудников!$B:$B,Справ_Сотрудников!$G:$G),"")) -> ЛюбаяМарка | I4: Поквартальная премия от продажи финансовых услуг | J4: =IF(ISBLANK(I4),"",IFERROR(_xlfn.XLOOKUP(I4,Справ_ВидыПремий!$B:$B,Справ_ВидыПремий!$E:$E)&"","")) -> % выполнения плана | K4: =IF(ISBLANK(I4),"",IFERROR(_xlfn.XLOOKUP(I4,Справ_ВидыПремий!$B:$B,Справ_ВидыПремий!$F:$F)&"","")) -> % | L4: 120 | M4: =IF(ISBLANK(I4),"",IFERROR(_xlfn.XLOOKUP(I4,Справ_ВидыПремий!$B:$B,Справ_ВидыПремий!$G:$G)&"","")) -> Плановое значение премии за КВ от продажи финансовых услуг | N4: =IF(ISBLANK(I4),"",IFERROR(_xlfn.XLOOKUP(I4,Справ_ВидыПремий!$B:$B,Справ_ВидыПремий!$H:$H)&"","")) -> руб. | O4: 50000 | P4: =IF(ISBLANK(A4),"",IFERROR(_xlfn.XLOOKUP(A4,Периоды!$A:$A,Периоды!$B:$B),"")) -> ЕЖЕКВАРТАЛЬНО | Q4: =IF(OR(ISBLANK(I4),R4="",ISBLANK(L4)),"",ROUND(IF(IFERROR(_xlfn.XLOOKUP(L4,INDIRECT("'"&R4&"'!$C:$C"),INDIRECT("'"&R4&"'!$G:$G"),"",-1),"")="% выполнения",L4/100,IFERROR(_xlfn.XLOOKUP(L4,INDIRECT("'"&R4&"'!$C:$C"),INDIRECT("'"&R4&"'!$E:$E"),0,-1),0))*IF(ISBLANK(O4),L4,O4)+IFERROR(_xlfn.XLOOKUP(L4,INDIRECT("'"&R4&"'!$C:$C"),INDIRECT("'"&R4&"'!$F:$F"),0,-1),0),2)) -> 60000 | R4: =IF(ISBLANK(I4),"",IFERROR(_xlfn.XLOOKUP(I4,Справ_ВидыПремий!$B:$B,Справ_ВидыПремий!$I:$I),"")) -> BT-004_Премия_КВФин
A5: Q3 2026 | B5: Лебедев Константин Юрьевич | C5: =IF(ISBLANK(B5),"",IFERROR(_xlfn.XLOOKUP(B5,Справ_Сотрудников!$B:$B,Справ_Сотрудников!$A:$A),"")) -> 10007 | D5: =IF(ISBLANK(B5),"",IFERROR(_xlfn.XLOOKUP(B5,Справ_Сотрудников!$B:$B,Справ_Сотрудников!$C:$C),"")) -> ДЦ Запад | E5: =IF(ISBLANK(B5),"",IFERROR(_xlfn.XLOOKUP(B5,Справ_Сотрудников!$B:$B,Справ_Сотрудников!$D:$D),"")) -> Финансовые услуги | F5: =IF(ISBLANK(B5),"",IFERROR(_xlfn.XLOOKUP(B5,Справ_Сотрудников!$B:$B,Справ_Сотрудников!$E:$E),"")) -> Отдел кредитования и страхования | G5: =IF(ISBLANK(B5),"",IFERROR(_xlfn.XLOOKUP(B5,Справ_Сотрудников!$B:$B,Справ_Сотрудников!$F:$F),"")) -> Менеджер по кредитованию и страхованию | H5: =IF(ISBLANK(B5),"",IFERROR(_xlfn.XLOOKUP(B5,Справ_Сотрудников!$B:$B,Справ_Сотрудников!$G:$G),"")) -> ЛюбаяМарка | I5: Поквартальная премия от продажи финансовых услуг | J5: =IF(ISBLANK(I5),"",IFERROR(_xlfn.XLOOKUP(I5,Справ_ВидыПремий!$B:$B,Справ_ВидыПремий!$E:$E)&"","")) -> % выполнения плана | K5: =IF(ISBLANK(I5),"",IFERROR(_xlfn.XLOOKUP(I5,Справ_ВидыПремий!$B:$B,Справ_ВидыПремий!$F:$F)&"","")) -> % | L5: 76 | M5: =IF(ISBLANK(I5),"",IFERROR(_xlfn.XLOOKUP(I5,Справ_ВидыПремий!$B:$B,Справ_ВидыПремий!$G:$G)&"","")) -> Плановое значение премии за КВ от продажи финансовых услуг | N5: =IF(ISBLANK(I5),"",IFERROR(_xlfn.XLOOKUP(I5,Справ_ВидыПремий!$B:$B,Справ_ВидыПремий!$H:$H)&"","")) -> руб. | O5: 50000 | P5: =IF(ISBLANK(A5),"",IFERROR(_xlfn.XLOOKUP(A5,Периоды!$A:$A,Периоды!$B:$B),"")) -> ЕЖЕКВАРТАЛЬНО | Q5: =IF(OR(ISBLANK(I5),R5="",ISBLANK(L5)),"",ROUND(IF(IFERROR(_xlfn.XLOOKUP(L5,INDIRECT("'"&R5&"'!$C:$C"),INDIRECT("'"&R5&"'!$G:$G"),"",-1),"")="% выполнения",L5/100,IFERROR(_xlfn.XLOOKUP(L5,INDIRECT("'"&R5&"'!$C:$C"),INDIRECT("'"&R5&"'!$E:$E"),0,-1),0))*IF(ISBLANK(O5),L5,O5)+IFERROR(_xlfn.XLOOKUP(L5,INDIRECT("'"&R5&"'!$C:$C"),INDIRECT("'"&R5&"'!$F:$F"),0,-1),0),2)) -> 25000 | R5: =IF(ISBLANK(I5),"",IFERROR(_xlfn.XLOOKUP(I5,Справ_ВидыПремий!$B:$B,Справ_ВидыПремий!$I:$I),"")) -> BT-004_Премия_КВФин
A6: 46327 | B6: Смирнова Елена Сергеевна | C6: =IF(ISBLANK(B6),"",IFERROR(_xlfn.XLOOKUP(B6,Справ_Сотрудников!$B:$B,Справ_Сотрудников!$A:$A),"")) -> 10002 | D6: =IF(ISBLANK(B6),"",IFERROR(_xlfn.XLOOKUP(B6,Справ_Сотрудников!$B:$B,Справ_Сотрудников!$C:$C),"")) -> ДЦ Север | E6: =IF(ISBLANK(B6),"",IFERROR(_xlfn.XLOOKUP(B6,Справ_Сотрудников!$B:$B,Справ_Сотрудников!$D:$D),"")) -> Продажи новых АМ | F6: =IF(ISBLANK(B6),"",IFERROR(_xlfn.XLOOKUP(B6,Справ_Сотрудников!$B:$B,Справ_Сотрудников!$E:$E),"")) -> Отдел продаж новых АМ | G6: =IF(ISBLANK(B6),"",IFERROR(_xlfn.XLOOKUP(B6,Справ_Сотрудников!$B:$B,Справ_Сотрудников!$F:$F),"")) -> Менеджер по продажам новых АМ | H6: =IF(ISBLANK(B6),"",IFERROR(_xlfn.XLOOKUP(B6,Справ_Сотрудников!$B:$B,Справ_Сотрудников!$G:$G),"")) -> Chery | I6: Премия за количество новых АМ | J6: =IF(ISBLANK(I6),"",IFERROR(_xlfn.XLOOKUP(I6,Справ_ВидыПремий!$B:$B,Справ_ВидыПремий!$E:$E)&"","")) -> Кол-во проданных автомобилей | K6: =IF(ISBLANK(I6),"",IFERROR(_xlfn.XLOOKUP(I6,Справ_ВидыПремий!$B:$B,Справ_ВидыПремий!$F:$F)&"","")) -> ед. | L6: 30 | M6: =IF(ISBLANK(I6),"",IFERROR(_xlfn.XLOOKUP(I6,Справ_ВидыПремий!$B:$B,Справ_ВидыПремий!$G:$G)&"","")) | N6: =IF(ISBLANK(I6),"",IFERROR(_xlfn.XLOOKUP(I6,Справ_ВидыПремий!$B:$B,Справ_ВидыПремий!$H:$H)&"","")) | P6: =IF(ISBLANK(A6),"",IFERROR(_xlfn.XLOOKUP(A6,Периоды!$A:$A,Периоды!$B:$B),"")) -> ЕЖЕМЕСЯЧНО | Q6: =IF(OR(ISBLANK(I6),R6="",ISBLANK(L6)),"",ROUND(IF(IFERROR(_xlfn.XLOOKUP(L6,INDIRECT("'"&R6&"'!$C:$C"),INDIRECT("'"&R6&"'!$G:$G"),"",-1),"")="% выполнения",L6/100,IFERROR(_xlfn.XLOOKUP(L6,INDIRECT("'"&R6&"'!$C:$C"),INDIRECT("'"&R6&"'!$E:$E"),0,-1),0))*IF(ISBLANK(O6),L6,O6)+IFERROR(_xlfn.XLOOKUP(L6,INDIRECT("'"&R6&"'!$C:$C"),INDIRECT("'"&R6&"'!$F:$F"),0,-1),0),2)) -> 510000 | R6: =IF(ISBLANK(I6),"",IFERROR(_xlfn.XLOOKUP(I6,Справ_ВидыПремий!$B:$B,Справ_ВидыПремий!$I:$I),"")) -> BT-001_Премия_КолвоАМ
A7: 46357 | B7: Морозова Анна Павловна | C7: =IF(ISBLANK(B7),"",IFERROR(_xlfn.XLOOKUP(B7,Справ_Сотрудников!$B:$B,Справ_Сотрудников!$A:$A),"")) -> 10006 | D7: =IF(ISBLANK(B7),"",IFERROR(_xlfn.XLOOKUP(B7,Справ_Сотрудников!$B:$B,Справ_Сотрудников!$C:$C),"")) -> ДЦ Юг | E7: =IF(ISBLANK(B7),"",IFERROR(_xlfn.XLOOKUP(B7,Справ_Сотрудников!$B:$B,Справ_Сотрудников!$D:$D),"")) -> Сервис | F7: =IF(ISBLANK(B7),"",IFERROR(_xlfn.XLOOKUP(B7,Справ_Сотрудников!$B:$B,Справ_Сотрудников!$E:$E),"")) -> Сервисный центр | G7: =IF(ISBLANK(B7),"",IFERROR(_xlfn.XLOOKUP(B7,Справ_Сотрудников!$B:$B,Справ_Сотрудников!$F:$F),"")) -> Мастер-консультант | H7: =IF(ISBLANK(B7),"",IFERROR(_xlfn.XLOOKUP(B7,Справ_Сотрудников!$B:$B,Справ_Сотрудников!$G:$G),"")) -> ЛюбаяМарка | I7: Премия за маржу сервиса | J7: =IF(ISBLANK(I7),"",IFERROR(_xlfn.XLOOKUP(I7,Справ_ВидыПремий!$B:$B,Справ_ВидыПремий!$E:$E)&"","")) -> % выполнения плана | K7: =IF(ISBLANK(I7),"",IFERROR(_xlfn.XLOOKUP(I7,Справ_ВидыПремий!$B:$B,Справ_ВидыПремий!$F:$F)&"","")) -> % | L7: 140 | M7: =IF(ISBLANK(I7),"",IFERROR(_xlfn.XLOOKUP(I7,Справ_ВидыПремий!$B:$B,Справ_ВидыПремий!$G:$G)&"","")) -> Маржа от продажи сервисных услуг | N7: =IF(ISBLANK(I7),"",IFERROR(_xlfn.XLOOKUP(I7,Справ_ВидыПремий!$B:$B,Справ_ВидыПремий!$H:$H)&"","")) -> руб. | O7: 800000 | P7: =IF(ISBLANK(A7),"",IFERROR(_xlfn.XLOOKUP(A7,Периоды!$A:$A,Периоды!$B:$B),"")) -> ЕЖЕМЕСЯЧНО | Q7: =IF(OR(ISBLANK(I7),R7="",ISBLANK(L7)),"",ROUND(IF(IFERROR(_xlfn.XLOOKUP(L7,INDIRECT("'"&R7&"'!$C:$C"),INDIRECT("'"&R7&"'!$G:$G"),"",-1),"")="% выполнения",L7/100,IFERROR(_xlfn.XLOOKUP(L7,INDIRECT("'"&R7&"'!$C:$C"),INDIRECT("'"&R7&"'!$E:$E"),0,-1),0))*IF(ISBLANK(O7),L7,O7)+IFERROR(_xlfn.XLOOKUP(L7,INDIRECT("'"&R7&"'!$C:$C"),INDIRECT("'"&R7&"'!$F:$F"),0,-1),0),2)) -> 960000 | R7: =IF(ISBLANK(I7),"",IFERROR(_xlfn.XLOOKUP(I7,Справ_ВидыПремий!$B:$B,Справ_ВидыПремий!$I:$I),"")) -> BT-003_Премия_МаржаСервис
A8: 46296 | B8: Иванов Алексей Петрович | C8: =IF(ISBLANK(B8),"",IFERROR(_xlfn.XLOOKUP(B8,Справ_Сотрудников!$B:$B,Справ_Сотрудников!$A:$A),"")) -> 10001 | D8: =IF(ISBLANK(B8),"",IFERROR(_xlfn.XLOOKUP(B8,Справ_Сотрудников!$B:$B,Справ_Сотрудников!$C:$C),"")) -> ДЦ Север | E8: =IF(ISBLANK(B8),"",IFERROR(_xlfn.XLOOKUP(B8,Справ_Сотрудников!$B:$B,Справ_Сотрудников!$D:$D),"")) -> Продажи новых АМ | F8: =IF(ISBLANK(B8),"",IFERROR(_xlfn.XLOOKUP(B8,Справ_Сотрудников!$B:$B,Справ_Сотрудников!$E:$E),"")) -> Отдел продаж новых АМ | G8: =IF(ISBLANK(B8),"",IFERROR(_xlfn.XLOOKUP(B8,Справ_Сотрудников!$B:$B,Справ_Сотрудников!$F:$F),"")) -> Менеджер по продажам новых АМ | H8: =IF(ISBLANK(B8),"",IFERROR(_xlfn.XLOOKUP(B8,Справ_Сотрудников!$B:$B,Справ_Сотрудников!$G:$G),"")) -> Haval | I8: Премия за кумулятивную маржу | J8: =IF(ISBLANK(I8),"",IFERROR(_xlfn.XLOOKUP(I8,Справ_ВидыПремий!$B:$B,Справ_ВидыПремий!$E:$E)&"","")) -> Кол-во проданных автомобилей | K8: =IF(ISBLANK(I8),"",IFERROR(_xlfn.XLOOKUP(I8,Справ_ВидыПремий!$B:$B,Справ_ВидыПремий!$F:$F)&"","")) -> ед. | L8: 12 | M8: =IF(ISBLANK(I8),"",IFERROR(_xlfn.XLOOKUP(I8,Справ_ВидыПремий!$B:$B,Справ_ВидыПремий!$G:$G)&"","")) -> Кумулятивная маржа при продаже нового АМ | N8: =IF(ISBLANK(I8),"",IFERROR(_xlfn.XLOOKUP(I8,Справ_ВидыПремий!$B:$B,Справ_ВидыПремий!$H:$H)&"","")) -> руб. | O8: 12000000 | P8: =IF(ISBLANK(A8),"",IFERROR(_xlfn.XLOOKUP(A8,Периоды!$A:$A,Периоды!$B:$B),"")) -> ЕЖЕМЕСЯЧНО | Q8: =IF(OR(ISBLANK(I8),R8="",ISBLANK(L8)),"",ROUND(IF(IFERROR(_xlfn.XLOOKUP(L8,INDIRECT("'"&R8&"'!$C:$C"),INDIRECT("'"&R8&"'!$G:$G"),"",-1),"")="% выполнения",L8/100,IFERROR(_xlfn.XLOOKUP(L8,INDIRECT("'"&R8&"'!$C:$C"),INDIRECT("'"&R8&"'!$E:$E"),0,-1),0))*IF(ISBLANK(O8),L8,O8)+IFERROR(_xlfn.XLOOKUP(L8,INDIRECT("'"&R8&"'!$C:$C"),INDIRECT("'"&R8&"'!$F:$F"),0,-1),0),2)) -> 480000 | R8: =IF(ISBLANK(I8),"",IFERROR(_xlfn.XLOOKUP(I8,Справ_ВидыПремий!$B:$B,Справ_ВидыПремий!$I:$I),"")) -> BT-002_Премия_КумМаржа
A9: Q3 2026 | B9: Лебедев Константин Юрьевич | C9: =IF(ISBLANK(B9),"",IFERROR(_xlfn.XLOOKUP(B9,Справ_Сотрудников!$B:$B,Справ_Сотрудников!$A:$A),"")) -> 10007 | D9: =IF(ISBLANK(B9),"",IFERROR(_xlfn.XLOOKUP(B9,Справ_Сотрудников!$B:$B,Справ_Сотрудников!$C:$C),"")) -> ДЦ Запад | E9: =IF(ISBLANK(B9),"",IFERROR(_xlfn.XLOOKUP(B9,Справ_Сотрудников!$B:$B,Справ_Сотрудников!$D:$D),"")) -> Финансовые услуги | F9: =IF(ISBLANK(B9),"",IFERROR(_xlfn.XLOOKUP(B9,Справ_Сотрудников!$B:$B,Справ_Сотрудников!$E:$E),"")) -> Отдел кредитования и страхования | G9: =IF(ISBLANK(B9),"",IFERROR(_xlfn.XLOOKUP(B9,Справ_Сотрудников!$B:$B,Справ_Сотрудников!$F:$F),"")) -> Менеджер по кредитованию и страхованию | H9: =IF(ISBLANK(B9),"",IFERROR(_xlfn.XLOOKUP(B9,Справ_Сотрудников!$B:$B,Справ_Сотрудников!$G:$G),"")) -> ЛюбаяМарка | I9: Поквартальная премия от продажи финансовых услуг | J9: =IF(ISBLANK(I9),"",IFERROR(_xlfn.XLOOKUP(I9,Справ_ВидыПремий!$B:$B,Справ_ВидыПремий!$E:$E)&"","")) -> % выполнения плана | K9: =IF(ISBLANK(I9),"",IFERROR(_xlfn.XLOOKUP(I9,Справ_ВидыПремий!$B:$B,Справ_ВидыПремий!$F:$F)&"","")) -> % | L9: 30 | M9: =IF(ISBLANK(I9),"",IFERROR(_xlfn.XLOOKUP(I9,Справ_ВидыПремий!$B:$B,Справ_ВидыПремий!$G:$G)&"","")) -> Плановое значение премии за КВ от продажи финансовых услуг | N9: =IF(ISBLANK(I9),"",IFERROR(_xlfn.XLOOKUP(I9,Справ_ВидыПремий!$B:$B,Справ_ВидыПремий!$H:$H)&"","")) -> руб. | O9: 1000000 | P9: =IF(ISBLANK(A9),"",IFERROR(_xlfn.XLOOKUP(A9,Периоды!$A:$A,Периоды!$B:$B),"")) -> ЕЖЕКВАРТАЛЬНО | Q9: =IF(OR(ISBLANK(I9),R9="",ISBLANK(L9)),"",ROUND(IF(IFERROR(_xlfn.XLOOKUP(L9,INDIRECT("'"&R9&"'!$C:$C"),INDIRECT("'"&R9&"'!$G:$G"),"",-1),"")="% выполнения",L9/100,IFERROR(_xlfn.XLOOKUP(L9,INDIRECT("'"&R9&"'!$C:$C"),INDIRECT("'"&R9&"'!$E:$E"),0,-1),0))*IF(ISBLANK(O9),L9,O9)+IFERROR(_xlfn.XLOOKUP(L9,INDIRECT("'"&R9&"'!$C:$C"),INDIRECT("'"&R9&"'!$F:$F"),0,-1),0),2)) -> 500000 | R9: =IF(ISBLANK(I9),"",IFERROR(_xlfn.XLOOKUP(I9,Справ_ВидыПремий!$B:$B,Справ_ВидыПремий!$I:$I),"")) -> BT-004_Премия_КВФин
A10: 46357 | B10: Иванов Алексей Петрович | C10: =IF(ISBLANK(B10),"",IFERROR(_xlfn.XLOOKUP(B10,Справ_Сотрудников!$B:$B,Справ_Сотрудников!$A:$A),"")) -> 10001 | D10: =IF(ISBLANK(B10),"",IFERROR(_xlfn.XLOOKUP(B10,Справ_Сотрудников!$B:$B,Справ_Сотрудников!$C:$C),"")) -> ДЦ Север | E10: =IF(ISBLANK(B10),"",IFERROR(_xlfn.XLOOKUP(B10,Справ_Сотрудников!$B:$B,Справ_Сотрудников!$D:$D),"")) -> Продажи новых АМ | F10: =IF(ISBLANK(B10),"",IFERROR(_xlfn.XLOOKUP(B10,Справ_Сотрудников!$B:$B,Справ_Сотрудников!$E:$E),"")) -> Отдел продаж новых АМ | G10: =IF(ISBLANK(B10),"",IFERROR(_xlfn.XLOOKUP(B10,Справ_Сотрудников!$B:$B,Справ_Сотрудников!$F:$F),"")) -> Менеджер по продажам новых АМ | H10: =IF(ISBLANK(B10),"",IFERROR(_xlfn.XLOOKUP(B10,Справ_Сотрудников!$B:$B,Справ_Сотрудников!$G:$G),"")) -> Haval | I10: Премия за количество новых АМ | J10: =IF(ISBLANK(I10),"",IFERROR(_xlfn.XLOOKUP(I10,Справ_ВидыПремий!$B:$B,Справ_ВидыПремий!$E:$E)&"","")) -> Кол-во проданных автомобилей | K10: =IF(ISBLANK(I10),"",IFERROR(_xlfn.XLOOKUP(I10,Справ_ВидыПремий!$B:$B,Справ_ВидыПремий!$F:$F)&"","")) -> ед. | L10: 45 | M10: =IF(ISBLANK(I10),"",IFERROR(_xlfn.XLOOKUP(I10,Справ_ВидыПремий!$B:$B,Справ_ВидыПремий!$G:$G)&"","")) | N10: =IF(ISBLANK(I10),"",IFERROR(_xlfn.XLOOKUP(I10,Справ_ВидыПремий!$B:$B,Справ_ВидыПремий!$H:$H)&"","")) | P10: =IF(ISBLANK(A10),"",IFERROR(_xlfn.XLOOKUP(A10,Периоды!$A:$A,Периоды!$B:$B),"")) -> ЕЖЕМЕСЯЧНО | Q10: =IF(OR(ISBLANK(I10),R10="",ISBLANK(L10)),"",ROUND(IF(IFERROR(_xlfn.XLOOKUP(L10,INDIRECT("'"&R10&"'!$C:$C"),INDIRECT("'"&R10&"'!$G:$G"),"",-1),"")="% выполнения",L10/100,IFERROR(_xlfn.XLOOKUP(L10,INDIRECT("'"&R10&"'!$C:$C"),INDIRECT("'"&R10&"'!$E:$E"),0,-1),0))*IF(ISBLANK(O10),L10,O10)+IFERROR(_xlfn.XLOOKUP(L10,INDIRECT("'"&R10&"'!$C:$C"),INDIRECT("'"&R10&"'!$F:$F"),0,-1),0),2)) -> 765000 | R10: =IF(ISBLANK(I10),"",IFERROR(_xlfn.XLOOKUP(I10,Справ_ВидыПремий!$B:$B,Справ_ВидыПремий!$I:$I),"")) -> BT-001_Премия_КолвоАМ
C11: =IF(ISBLANK(B11),"",IFERROR(_xlfn.XLOOKUP(B11,Справ_Сотрудников!$B:$B,Справ_Сотрудников!$A:$A),"")) | D11: =IF(ISBLANK(B11),"",IFERROR(_xlfn.XLOOKUP(B11,Справ_Сотрудников!$B:$B,Справ_Сотрудников!$C:$C),"")) | E11: =IF(ISBLANK(B11),"",IFERROR(_xlfn.XLOOKUP(B11,Справ_Сотрудников!$B:$B,Справ_Сотрудников!$D:$D),"")) | F11: =IF(ISBLANK(B11),"",IFERROR(_xlfn.XLOOKUP(B11,Справ_Сотрудников!$B:$B,Справ_Сотрудников!$E:$E),"")) | G11: =IF(ISBLANK(B11),"",IFERROR(_xlfn.XLOOKUP(B11,Справ_Сотрудников!$B:$B,Справ_Сотрудников!$F:$F),"")) | H11: =IF(ISBLANK(B11),"",IFERROR(_xlfn.XLOOKUP(B11,Справ_Сотрудников!$B:$B,Справ_Сотрудников!$G:$G),"")) | J11: =IF(ISBLANK(I11),"",IFERROR(_xlfn.XLOOKUP(I11,Справ_ВидыПремий!$B:$B,Справ_ВидыПремий!$E:$E)&"","")) | K11: =IF(ISBLANK(I11),"",IFERROR(_xlfn.XLOOKUP(I11,Справ_ВидыПремий!$B:$B,Справ_ВидыПремий!$F:$F)&"","")) | M11: =IF(ISBLANK(I11),"",IFERROR(_xlfn.XLOOKUP(I11,Справ_ВидыПремий!$B:$B,Справ_ВидыПремий!$G:$G)&"","")) | N11: =IF(ISBLANK(I11),"",IFERROR(_xlfn.XLOOKUP(I11,Справ_ВидыПремий!$B:$B,Справ_ВидыПремий!$H:$H)&"","")) | P11: =IF(ISBLANK(A11),"",IFERROR(_xlfn.XLOOKUP(A11,Периоды!$A:$A,Периоды!$B:$B),"")) | Q11: =IF(OR(ISBLANK(I11),R11="",ISBLANK(L11)),"",ROUND(IF(IFERROR(_xlfn.XLOOKUP(L11,INDIRECT("'"&R11&"'!$C:$C"),INDIRECT("'"&R11&"'!$G:$G"),"",-1),"")="% выполнения",L11/100,IFERROR(_xlfn.XLOOKUP(L11,INDIRECT("'"&R11&"'!$C:$C"),INDIRECT("'"&R11&"'!$E:$E"),0,-1),0))*IF(ISBLANK(O11),L11,O11)+IFERROR(_xlfn.XLOOKUP(L11,INDIRECT("'"&R11&"'!$C:$C"),INDIRECT("'"&R11&"'!$F:$F"),0,-1),0),2)) | R11: =IF(ISBLANK(I11),"",IFERROR(_xlfn.XLOOKUP(I11,Справ_ВидыПремий!$B:$B,Справ_ВидыПремий!$I:$I),""))
C12: =IF(ISBLANK(B12),"",IFERROR(_xlfn.XLOOKUP(B12,Справ_Сотрудников!$B:$B,Справ_Сотрудников!$A:$A),"")) | D12: =IF(ISBLANK(B12),"",IFERROR(_xlfn.XLOOKUP(B12,Справ_Сотрудников!$B:$B,Справ_Сотрудников!$C:$C),"")) | E12: =IF(ISBLANK(B12),"",IFERROR(_xlfn.XLOOKUP(B12,Справ_Сотрудников!$B:$B,Справ_Сотрудников!$D:$D),"")) | F12: =IF(ISBLANK(B12),"",IFERROR(_xlfn.XLOOKUP(B12,Справ_Сотрудников!$B:$B,Справ_Сотрудников!$E:$E),"")) | G12: =IF(ISBLANK(B12),"",IFERROR(_xlfn.XLOOKUP(B12,Справ_Сотрудников!$B:$B,Справ_Сотрудников!$F:$F),"")) | H12: =IF(ISBLANK(B12),"",IFERROR(_xlfn.XLOOKUP(B12,Справ_Сотрудников!$B:$B,Справ_Сотрудников!$G:$G),"")) | J12: =IF(ISBLANK(I12),"",IFERROR(_xlfn.XLOOKUP(I12,Справ_ВидыПремий!$B:$B,Справ_ВидыПремий!$E:$E)&"","")) | K12: =IF(ISBLANK(I12),"",IFERROR(_xlfn.XLOOKUP(I12,Справ_ВидыПремий!$B:$B,Справ_ВидыПремий!$F:$F)&"","")) | M12: =IF(ISBLANK(I12),"",IFERROR(_xlfn.XLOOKUP(I12,Справ_ВидыПремий!$B:$B,Справ_ВидыПремий!$G:$G)&"","")) | N12: =IF(ISBLANK(I12),"",IFERROR(_xlfn.XLOOKUP(I12,Справ_ВидыПремий!$B:$B,Справ_ВидыПремий!$H:$H)&"","")) | P12: =IF(ISBLANK(A12),"",IFERROR(_xlfn.XLOOKUP(A12,Периоды!$A:$A,Периоды!$B:$B),"")) | Q12: =IF(OR(ISBLANK(I12),R12="",ISBLANK(L12)),"",ROUND(IF(IFERROR(_xlfn.XLOOKUP(L12,INDIRECT("'"&R12&"'!$C:$C"),INDIRECT("'"&R12&"'!$G:$G"),"",-1),"")="% выполнения",L12/100,IFERROR(_xlfn.XLOOKUP(L12,INDIRECT("'"&R12&"'!$C:$C"),INDIRECT("'"&R12&"'!$E:$E"),0,-1),0))*IF(ISBLANK(O12),L12,O12)+IFERROR(_xlfn.XLOOKUP(L12,INDIRECT("'"&R12&"'!$C:$C"),INDIRECT("'"&R12&"'!$F:$F"),0,-1),0),2)) | R12: =IF(ISBLANK(I12),"",IFERROR(_xlfn.XLOOKUP(I12,Справ_ВидыПремий!$B:$B,Справ_ВидыПремий!$I:$I),""))
C13: =IF(ISBLANK(B13),"",IFERROR(_xlfn.XLOOKUP(B13,Справ_Сотрудников!$B:$B,Справ_Сотрудников!$A:$A),"")) | D13: =IF(ISBLANK(B13),"",IFERROR(_xlfn.XLOOKUP(B13,Справ_Сотрудников!$B:$B,Справ_Сотрудников!$C:$C),"")) | E13: =IF(ISBLANK(B13),"",IFERROR(_xlfn.XLOOKUP(B13,Справ_Сотрудников!$B:$B,Справ_Сотрудников!$D:$D),"")) | F13: =IF(ISBLANK(B13),"",IFERROR(_xlfn.XLOOKUP(B13,Справ_Сотрудников!$B:$B,Справ_Сотрудников!$E:$E),"")) | G13: =IF(ISBLANK(B13),"",IFERROR(_xlfn.XLOOKUP(B13,Справ_Сотрудников!$B:$B,Справ_Сотрудников!$F:$F),"")) | H13: =IF(ISBLANK(B13),"",IFERROR(_xlfn.XLOOKUP(B13,Справ_Сотрудников!$B:$B,Справ_Сотрудников!$G:$G),"")) | J13: =IF(ISBLANK(I13),"",IFERROR(_xlfn.XLOOKUP(I13,Справ_ВидыПремий!$B:$B,Справ_ВидыПремий!$E:$E)&"","")) | K13: =IF(ISBLANK(I13),"",IFERROR(_xlfn.XLOOKUP(I13,Справ_ВидыПремий!$B:$B,Справ_ВидыПремий!$F:$F)&"","")) | M13: =IF(ISBLANK(I13),"",IFERROR(_xlfn.XLOOKUP(I13,Справ_ВидыПремий!$B:$B,Справ_ВидыПремий!$G:$G)&"","")) | N13: =IF(ISBLANK(I13),"",IFERROR(_xlfn.XLOOKUP(I13,Справ_ВидыПремий!$B:$B,Справ_ВидыПремий!$H:$H)&"","")) | P13: =IF(ISBLANK(A13),"",IFERROR(_xlfn.XLOOKUP(A13,Периоды!$A:$A,Периоды!$B:$B),"")) | Q13: =IF(OR(ISBLANK(I13),R13="",ISBLANK(L13)),"",ROUND(IF(IFERROR(_xlfn.XLOOKUP(L13,INDIRECT("'"&R13&"'!$C:$C"),INDIRECT("'"&R13&"'!$G:$G"),"",-1),"")="% выполнения",L13/100,IFERROR(_xlfn.XLOOKUP(L13,INDIRECT("'"&R13&"'!$C:$C"),INDIRECT("'"&R13&"'!$E:$E"),0,-1),0))*IF(ISBLANK(O13),L13,O13)+IFERROR(_xlfn.XLOOKUP(L13,INDIRECT("'"&R13&"'!$C:$C"),INDIRECT("'"&R13&"'!$F:$F"),0,-1),0),2)) | R13: =IF(ISBLANK(I13),"",IFERROR(_xlfn.XLOOKUP(I13,Справ_ВидыПремий!$B:$B,Справ_ВидыПремий!$I:$I),""))
C14: =IF(ISBLANK(B14),"",IFERROR(_xlfn.XLOOKUP(B14,Справ_Сотрудников!$B:$B,Справ_Сотрудников!$A:$A),"")) | D14: =IF(ISBLANK(B14),"",IFERROR(_xlfn.XLOOKUP(B14,Справ_Сотрудников!$B:$B,Справ_Сотрудников!$C:$C),"")) | E14: =IF(ISBLANK(B14),"",IFERROR(_xlfn.XLOOKUP(B14,Справ_Сотрудников!$B:$B,Справ_Сотрудников!$D:$D),"")) | F14: =IF(ISBLANK(B14),"",IFERROR(_xlfn.XLOOKUP(B14,Справ_Сотрудников!$B:$B,Справ_Сотрудников!$E:$E),"")) | G14: =IF(ISBLANK(B14),"",IFERROR(_xlfn.XLOOKUP(B14,Справ_Сотрудников!$B:$B,Справ_Сотрудников!$F:$F),"")) | H14: =IF(ISBLANK(B14),"",IFERROR(_xlfn.XLOOKUP(B14,Справ_Сотрудников!$B:$B,Справ_Сотрудников!$G:$G),"")) | J14: =IF(ISBLANK(I14),"",IFERROR(_xlfn.XLOOKUP(I14,Справ_ВидыПремий!$B:$B,Справ_ВидыПремий!$E:$E)&"","")) | K14: =IF(ISBLANK(I14),"",IFERROR(_xlfn.XLOOKUP(I14,Справ_ВидыПремий!$B:$B,Справ_ВидыПремий!$F:$F)&"","")) | M14: =IF(ISBLANK(I14),"",IFERROR(_xlfn.XLOOKUP(I14,Справ_ВидыПремий!$B:$B,Справ_ВидыПремий!$G:$G)&"","")) | N14: =IF(ISBLANK(I14),"",IFERROR(_xlfn.XLOOKUP(I14,Справ_ВидыПремий!$B:$B,Справ_ВидыПремий!$H:$H)&"","")) | P14: =IF(ISBLANK(A14),"",IFERROR(_xlfn.XLOOKUP(A14,Периоды!$A:$A,Периоды!$B:$B),"")) | Q14: =IF(OR(ISBLANK(I14),R14="",ISBLANK(L14)),"",ROUND(IF(IFERROR(_xlfn.XLOOKUP(L14,INDIRECT("'"&R14&"'!$C:$C"),INDIRECT("'"&R14&"'!$G:$G"),"",-1),"")="% выполнения",L14/100,IFERROR(_xlfn.XLOOKUP(L14,INDIRECT("'"&R14&"'!$C:$C"),INDIRECT("'"&R14&"'!$E:$E"),0,-1),0))*IF(ISBLANK(O14),L14,O14)+IFERROR(_xlfn.XLOOKUP(L14,INDIRECT("'"&R14&"'!$C:$C"),INDIRECT("'"&R14&"'!$F:$F"),0,-1),0),2)) | R14: =IF(ISBLANK(I14),"",IFERROR(_xlfn.XLOOKUP(I14,Справ_ВидыПремий!$B:$B,Справ_ВидыПремий!$I:$I),""))
C15: =IF(ISBLANK(B15),"",IFERROR(_xlfn.XLOOKUP(B15,Справ_Сотрудников!$B:$B,Справ_Сотрудников!$A:$A),"")) | D15: =IF(ISBLANK(B15),"",IFERROR(_xlfn.XLOOKUP(B15,Справ_Сотрудников!$B:$B,Справ_Сотрудников!$C:$C),"")) | E15: =IF(ISBLANK(B15),"",IFERROR(_xlfn.XLOOKUP(B15,Справ_Сотрудников!$B:$B,Справ_Сотрудников!$D:$D),"")) | F15: =IF(ISBLANK(B15),"",IFERROR(_xlfn.XLOOKUP(B15,Справ_Сотрудников!$B:$B,Справ_Сотрудников!$E:$E),"")) | G15: =IF(ISBLANK(B15),"",IFERROR(_xlfn.XLOOKUP(B15,Справ_Сотрудников!$B:$B,Справ_Сотрудников!$F:$F),"")) | H15: =IF(ISBLANK(B15),"",IFERROR(_xlfn.XLOOKUP(B15,Справ_Сотрудников!$B:$B,Справ_Сотрудников!$G:$G),"")) | J15: =IF(ISBLANK(I15),"",IFERROR(_xlfn.XLOOKUP(I15,Справ_ВидыПремий!$B:$B,Справ_ВидыПремий!$E:$E)&"","")) | K15: =IF(ISBLANK(I15),"",IFERROR(_xlfn.XLOOKUP(I15,Справ_ВидыПремий!$B:$B,Справ_ВидыПремий!$F:$F)&"","")) | M15: =IF(ISBLANK(I15),"",IFERROR(_xlfn.XLOOKUP(I15,Справ_ВидыПремий!$B:$B,Справ_ВидыПремий!$G:$G)&"","")) | N15: =IF(ISBLANK(I15),"",IFERROR(_xlfn.XLOOKUP(I15,Справ_ВидыПремий!$B:$B,Справ_ВидыПремий!$H:$H)&"","")) | P15: =IF(ISBLANK(A15),"",IFERROR(_xlfn.XLOOKUP(A15,Периоды!$A:$A,Периоды!$B:$B),"")) | Q15: =IF(OR(ISBLANK(I15),R15="",ISBLANK(L15)),"",ROUND(IF(IFERROR(_xlfn.XLOOKUP(L15,INDIRECT("'"&R15&"'!$C:$C"),INDIRECT("'"&R15&"'!$G:$G"),"",-1),"")="% выполнения",L15/100,IFERROR(_xlfn.XLOOKUP(L15,INDIRECT("'"&R15&"'!$C:$C"),INDIRECT("'"&R15&"'!$E:$E"),0,-1),0))*IF(ISBLANK(O15),L15,O15)+IFERROR(_xlfn.XLOOKUP(L15,INDIRECT("'"&R15&"'!$C:$C"),INDIRECT("'"&R15&"'!$F:$F"),0,-1),0),2)) | R15: =IF(ISBLANK(I15),"",IFERROR(_xlfn.XLOOKUP(I15,Справ_ВидыПремий!$B:$B,Справ_ВидыПремий!$I:$I),""))
C16: =IF(ISBLANK(B16),"",IFERROR(_xlfn.XLOOKUP(B16,Справ_Сотрудников!$B:$B,Справ_Сотрудников!$A:$A),"")) | D16: =IF(ISBLANK(B16),"",IFERROR(_xlfn.XLOOKUP(B16,Справ_Сотрудников!$B:$B,Справ_Сотрудников!$C:$C),"")) | E16: =IF(ISBLANK(B16),"",IFERROR(_xlfn.XLOOKUP(B16,Справ_Сотрудников!$B:$B,Справ_Сотрудников!$D:$D),"")) | F16: =IF(ISBLANK(B16),"",IFERROR(_xlfn.XLOOKUP(B16,Справ_Сотрудников!$B:$B,Справ_Сотрудников!$E:$E),"")) | G16: =IF(ISBLANK(B16),"",IFERROR(_xlfn.XLOOKUP(B16,Справ_Сотрудников!$B:$B,Справ_Сотрудников!$F:$F),"")) | H16: =IF(ISBLANK(B16),"",IFERROR(_xlfn.XLOOKUP(B16,Справ_Сотрудников!$B:$B,Справ_Сотрудников!$G:$G),"")) | J16: =IF(ISBLANK(I16),"",IFERROR(_xlfn.XLOOKUP(I16,Справ_ВидыПремий!$B:$B,Справ_ВидыПремий!$E:$E)&"","")) | K16: =IF(ISBLANK(I16),"",IFERROR(_xlfn.XLOOKUP(I16,Справ_ВидыПремий!$B:$B,Справ_ВидыПремий!$F:$F)&"","")) | M16: =IF(ISBLANK(I16),"",IFERROR(_xlfn.XLOOKUP(I16,Справ_ВидыПремий!$B:$B,Справ_ВидыПремий!$G:$G)&"","")) | N16: =IF(ISBLANK(I16),"",IFERROR(_xlfn.XLOOKUP(I16,Справ_ВидыПремий!$B:$B,Справ_ВидыПремий!$H:$H)&"","")) | P16: =IF(ISBLANK(A16),"",IFERROR(_xlfn.XLOOKUP(A16,Периоды!$A:$A,Периоды!$B:$B),"")) | Q16: =IF(OR(ISBLANK(I16),R16="",ISBLANK(L16)),"",ROUND(IF(IFERROR(_xlfn.XLOOKUP(L16,INDIRECT("'"&R16&"'!$C:$C"),INDIRECT("'"&R16&"'!$G:$G"),"",-1),"")="% выполнения",L16/100,IFERROR(_xlfn.XLOOKUP(L16,INDIRECT("'"&R16&"'!$C:$C"),INDIRECT("'"&R16&"'!$E:$E"),0,-1),0))*IF(ISBLANK(O16),L16,O16)+IFERROR(_xlfn.XLOOKUP(L16,INDIRECT("'"&R16&"'!$C:$C"),INDIRECT("'"&R16&"'!$F:$F"),0,-1),0),2)) | R16: =IF(ISBLANK(I16),"",IFERROR(_xlfn.XLOOKUP(I16,Справ_ВидыПремий!$B:$B,Справ_ВидыПремий!$I:$I),""))
C17: =IF(ISBLANK(B17),"",IFERROR(_xlfn.XLOOKUP(B17,Справ_Сотрудников!$B:$B,Справ_Сотрудников!$A:$A),"")) | D17: =IF(ISBLANK(B17),"",IFERROR(_xlfn.XLOOKUP(B17,Справ_Сотрудников!$B:$B,Справ_Сотрудников!$C:$C),"")) | E17: =IF(ISBLANK(B17),"",IFERROR(_xlfn.XLOOKUP(B17,Справ_Сотрудников!$B:$B,Справ_Сотрудников!$D:$D),"")) | F17: =IF(ISBLANK(B17),"",IFERROR(_xlfn.XLOOKUP(B17,Справ_Сотрудников!$B:$B,Справ_Сотрудников!$E:$E),"")) | G17: =IF(ISBLANK(B17),"",IFERROR(_xlfn.XLOOKUP(B17,Справ_Сотрудников!$B:$B,Справ_Сотрудников!$F:$F),"")) | H17: =IF(ISBLANK(B17),"",IFERROR(_xlfn.XLOOKUP(B17,Справ_Сотрудников!$B:$B,Справ_Сотрудников!$G:$G),"")) | J17: =IF(ISBLANK(I17),"",IFERROR(_xlfn.XLOOKUP(I17,Справ_ВидыПремий!$B:$B,Справ_ВидыПремий!$E:$E)&"","")) | K17: =IF(ISBLANK(I17),"",IFERROR(_xlfn.XLOOKUP(I17,Справ_ВидыПремий!$B:$B,Справ_ВидыПремий!$F:$F)&"","")) | M17: =IF(ISBLANK(I17),"",IFERROR(_xlfn.XLOOKUP(I17,Справ_ВидыПремий!$B:$B,Справ_ВидыПремий!$G:$G)&"","")) | N17: =IF(ISBLANK(I17),"",IFERROR(_xlfn.XLOOKUP(I17,Справ_ВидыПремий!$B:$B,Справ_ВидыПремий!$H:$H)&"","")) | P17: =IF(ISBLANK(A17),"",IFERROR(_xlfn.XLOOKUP(A17,Периоды!$A:$A,Периоды!$B:$B),"")) | Q17: =IF(OR(ISBLANK(I17),R17="",ISBLANK(L17)),"",ROUND(IF(IFERROR(_xlfn.XLOOKUP(L17,INDIRECT("'"&R17&"'!$C:$C"),INDIRECT("'"&R17&"'!$G:$G"),"",-1),"")="% выполнения",L17/100,IFERROR(_xlfn.XLOOKUP(L17,INDIRECT("'"&R17&"'!$C:$C"),INDIRECT("'"&R17&"'!$E:$E"),0,-1),0))*IF(ISBLANK(O17),L17,O17)+IFERROR(_xlfn.XLOOKUP(L17,INDIRECT("'"&R17&"'!$C:$C"),INDIRECT("'"&R17&"'!$F:$F"),0,-1),0),2)) | R17: =IF(ISBLANK(I17),"",IFERROR(_xlfn.XLOOKUP(I17,Справ_ВидыПремий!$B:$B,Справ_ВидыПремий!$I:$I),""))
C18: =IF(ISBLANK(B18),"",IFERROR(_xlfn.XLOOKUP(B18,Справ_Сотрудников!$B:$B,Справ_Сотрудников!$A:$A),"")) | D18: =IF(ISBLANK(B18),"",IFERROR(_xlfn.XLOOKUP(B18,Справ_Сотрудников!$B:$B,Справ_Сотрудников!$C:$C),"")) | E18: =IF(ISBLANK(B18),"",IFERROR(_xlfn.XLOOKUP(B18,Справ_Сотрудников!$B:$B,Справ_Сотрудников!$D:$D),"")) | F18: =IF(ISBLANK(B18),"",IFERROR(_xlfn.XLOOKUP(B18,Справ_Сотрудников!$B:$B,Справ_Сотрудников!$E:$E),"")) | G18: =IF(ISBLANK(B18),"",IFERROR(_xlfn.XLOOKUP(B18,Справ_Сотрудников!$B:$B,Справ_Сотрудников!$F:$F),"")) | H18: =IF(ISBLANK(B18),"",IFERROR(_xlfn.XLOOKUP(B18,Справ_Сотрудников!$B:$B,Справ_Сотрудников!$G:$G),"")) | J18: =IF(ISBLANK(I18),"",IFERROR(_xlfn.XLOOKUP(I18,Справ_ВидыПремий!$B:$B,Справ_ВидыПремий!$E:$E)&"","")) | K18: =IF(ISBLANK(I18),"",IFERROR(_xlfn.XLOOKUP(I18,Справ_ВидыПремий!$B:$B,Справ_ВидыПремий!$F:$F)&"","")) | M18: =IF(ISBLANK(I18),"",IFERROR(_xlfn.XLOOKUP(I18,Справ_ВидыПремий!$B:$B,Справ_ВидыПремий!$G:$G)&"","")) | N18: =IF(ISBLANK(I18),"",IFERROR(_xlfn.XLOOKUP(I18,Справ_ВидыПремий!$B:$B,Справ_ВидыПремий!$H:$H)&"","")) | P18: =IF(ISBLANK(A18),"",IFERROR(_xlfn.XLOOKUP(A18,Периоды!$A:$A,Периоды!$B:$B),"")) | Q18: =IF(OR(ISBLANK(I18),R18="",ISBLANK(L18)),"",ROUND(IF(IFERROR(_xlfn.XLOOKUP(L18,INDIRECT("'"&R18&"'!$C:$C"),INDIRECT("'"&R18&"'!$G:$G"),"",-1),"")="% выполнения",L18/100,IFERROR(_xlfn.XLOOKUP(L18,INDIRECT("'"&R18&"'!$C:$C"),INDIRECT("'"&R18&"'!$E:$E"),0,-1),0))*IF(ISBLANK(O18),L18,O18)+IFERROR(_xlfn.XLOOKUP(L18,INDIRECT("'"&R18&"'!$C:$C"),INDIRECT("'"&R18&"'!$F:$F"),0,-1),0),2)) | R18: =IF(ISBLANK(I18),"",IFERROR(_xlfn.XLOOKUP(I18,Справ_ВидыПремий!$B:$B,Справ_ВидыПремий!$I:$I),""))
C19: =IF(ISBLANK(B19),"",IFERROR(_xlfn.XLOOKUP(B19,Справ_Сотрудников!$B:$B,Справ_Сотрудников!$A:$A),"")) | D19: =IF(ISBLANK(B19),"",IFERROR(_xlfn.XLOOKUP(B19,Справ_Сотрудников!$B:$B,Справ_Сотрудников!$C:$C),"")) | E19: =IF(ISBLANK(B19),"",IFERROR(_xlfn.XLOOKUP(B19,Справ_Сотрудников!$B:$B,Справ_Сотрудников!$D:$D),"")) | F19: =IF(ISBLANK(B19),"",IFERROR(_xlfn.XLOOKUP(B19,Справ_Сотрудников!$B:$B,Справ_Сотрудников!$E:$E),"")) | G19: =IF(ISBLANK(B19),"",IFERROR(_xlfn.XLOOKUP(B19,Справ_Сотрудников!$B:$B,Справ_Сотрудников!$F:$F),"")) | H19: =IF(ISBLANK(B19),"",IFERROR(_xlfn.XLOOKUP(B19,Справ_Сотрудников!$B:$B,Справ_Сотрудников!$G:$G),"")) | J19: =IF(ISBLANK(I19),"",IFERROR(_xlfn.XLOOKUP(I19,Справ_ВидыПремий!$B:$B,Справ_ВидыПремий!$E:$E)&"","")) | K19: =IF(ISBLANK(I19),"",IFERROR(_xlfn.XLOOKUP(I19,Справ_ВидыПремий!$B:$B,Справ_ВидыПремий!$F:$F)&"","")) | M19: =IF(ISBLANK(I19),"",IFERROR(_xlfn.XLOOKUP(I19,Справ_ВидыПремий!$B:$B,Справ_ВидыПремий!$G:$G)&"","")) | N19: =IF(ISBLANK(I19),"",IFERROR(_xlfn.XLOOKUP(I19,Справ_ВидыПремий!$B:$B,Справ_ВидыПремий!$H:$H)&"","")) | P19: =IF(ISBLANK(A19),"",IFERROR(_xlfn.XLOOKUP(A19,Периоды!$A:$A,Периоды!$B:$B),"")) | Q19: =IF(OR(ISBLANK(I19),R19="",ISBLANK(L19)),"",ROUND(IF(IFERROR(_xlfn.XLOOKUP(L19,INDIRECT("'"&R19&"'!$C:$C"),INDIRECT("'"&R19&"'!$G:$G"),"",-1),"")="% выполнения",L19/100,IFERROR(_xlfn.XLOOKUP(L19,INDIRECT("'"&R19&"'!$C:$C"),INDIRECT("'"&R19&"'!$E:$E"),0,-1),0))*IF(ISBLANK(O19),L19,O19)+IFERROR(_xlfn.XLOOKUP(L19,INDIRECT("'"&R19&"'!$C:$C"),INDIRECT("'"&R19&"'!$F:$F"),0,-1),0),2)) | R19: =IF(ISBLANK(I19),"",IFERROR(_xlfn.XLOOKUP(I19,Справ_ВидыПремий!$B:$B,Справ_ВидыПремий!$I:$I),""))
C20: =IF(ISBLANK(B20),"",IFERROR(_xlfn.XLOOKUP(B20,Справ_Сотрудников!$B:$B,Справ_Сотрудников!$A:$A),"")) | D20: =IF(ISBLANK(B20),"",IFERROR(_xlfn.XLOOKUP(B20,Справ_Сотрудников!$B:$B,Справ_Сотрудников!$C:$C),"")) | E20: =IF(ISBLANK(B20),"",IFERROR(_xlfn.XLOOKUP(B20,Справ_Сотрудников!$B:$B,Справ_Сотрудников!$D:$D),"")) | F20: =IF(ISBLANK(B20),"",IFERROR(_xlfn.XLOOKUP(B20,Справ_Сотрудников!$B:$B,Справ_Сотрудников!$E:$E),"")) | G20: =IF(ISBLANK(B20),"",IFERROR(_xlfn.XLOOKUP(B20,Справ_Сотрудников!$B:$B,Справ_Сотрудников!$F:$F),"")) | H20: =IF(ISBLANK(B20),"",IFERROR(_xlfn.XLOOKUP(B20,Справ_Сотрудников!$B:$B,Справ_Сотрудников!$G:$G),"")) | J20: =IF(ISBLANK(I20),"",IFERROR(_xlfn.XLOOKUP(I20,Справ_ВидыПремий!$B:$B,Справ_ВидыПремий!$E:$E)&"","")) | K20: =IF(ISBLANK(I20),"",IFERROR(_xlfn.XLOOKUP(I20,Справ_ВидыПремий!$B:$B,Справ_ВидыПремий!$F:$F)&"","")) | M20: =IF(ISBLANK(I20),"",IFERROR(_xlfn.XLOOKUP(I20,Справ_ВидыПремий!$B:$B,Справ_ВидыПремий!$G:$G)&"","")) | N20: =IF(ISBLANK(I20),"",IFERROR(_xlfn.XLOOKUP(I20,Справ_ВидыПремий!$B:$B,Справ_ВидыПремий!$H:$H)&"","")) | P20: =IF(ISBLANK(A20),"",IFERROR(_xlfn.XLOOKUP(A20,Периоды!$A:$A,Периоды!$B:$B),"")) | Q20: =IF(OR(ISBLANK(I20),R20="",ISBLANK(L20)),"",ROUND(IF(IFERROR(_xlfn.XLOOKUP(L20,INDIRECT("'"&R20&"'!$C:$C"),INDIRECT("'"&R20&"'!$G:$G"),"",-1),"")="% выполнения",L20/100,IFERROR(_xlfn.XLOOKUP(L20,INDIRECT("'"&R20&"'!$C:$C"),INDIRECT("'"&R20&"'!$E:$E"),0,-1),0))*IF(ISBLANK(O20),L20,O20)+IFERROR(_xlfn.XLOOKUP(L20,INDIRECT("'"&R20&"'!$C:$C"),INDIRECT("'"&R20&"'!$F:$F"),0,-1),0),2)) | R20: =IF(ISBLANK(I20),"",IFERROR(_xlfn.XLOOKUP(I20,Справ_ВидыПремий!$B:$B,Справ_ВидыПремий!$I:$I),""))
C21: =IF(ISBLANK(B21),"",IFERROR(_xlfn.XLOOKUP(B21,Справ_Сотрудников!$B:$B,Справ_Сотрудников!$A:$A),"")) | D21: =IF(ISBLANK(B21),"",IFERROR(_xlfn.XLOOKUP(B21,Справ_Сотрудников!$B:$B,Справ_Сотрудников!$C:$C),"")) | E21: =IF(ISBLANK(B21),"",IFERROR(_xlfn.XLOOKUP(B21,Справ_Сотрудников!$B:$B,Справ_Сотрудников!$D:$D),"")) | F21: =IF(ISBLANK(B21),"",IFERROR(_xlfn.XLOOKUP(B21,Справ_Сотрудников!$B:$B,Справ_Сотрудников!$E:$E),"")) | G21: =IF(ISBLANK(B21),"",IFERROR(_xlfn.XLOOKUP(B21,Справ_Сотрудников!$B:$B,Справ_Сотрудников!$F:$F),"")) | H21: =IF(ISBLANK(B21),"",IFERROR(_xlfn.XLOOKUP(B21,Справ_Сотрудников!$B:$B,Справ_Сотрудников!$G:$G),"")) | J21: =IF(ISBLANK(I21),"",IFERROR(_xlfn.XLOOKUP(I21,Справ_ВидыПремий!$B:$B,Справ_ВидыПремий!$E:$E)&"","")) | K21: =IF(ISBLANK(I21),"",IFERROR(_xlfn.XLOOKUP(I21,Справ_ВидыПремий!$B:$B,Справ_ВидыПремий!$F:$F)&"","")) | M21: =IF(ISBLANK(I21),"",IFERROR(_xlfn.XLOOKUP(I21,Справ_ВидыПремий!$B:$B,Справ_ВидыПремий!$G:$G)&"","")) | N21: =IF(ISBLANK(I21),"",IFERROR(_xlfn.XLOOKUP(I21,Справ_ВидыПремий!$B:$B,Справ_ВидыПремий!$H:$H)&"","")) | P21: =IF(ISBLANK(A21),"",IFERROR(_xlfn.XLOOKUP(A21,Периоды!$A:$A,Периоды!$B:$B),"")) | Q21: =IF(OR(ISBLANK(I21),R21="",ISBLANK(L21)),"",ROUND(IF(IFERROR(_xlfn.XLOOKUP(L21,INDIRECT("'"&R21&"'!$C:$C"),INDIRECT("'"&R21&"'!$G:$G"),"",-1),"")="% выполнения",L21/100,IFERROR(_xlfn.XLOOKUP(L21,INDIRECT("'"&R21&"'!$C:$C"),INDIRECT("'"&R21&"'!$E:$E"),0,-1),0))*IF(ISBLANK(O21),L21,O21)+IFERROR(_xlfn.XLOOKUP(L21,INDIRECT("'"&R21&"'!$C:$C"),INDIRECT("'"&R21&"'!$F:$F"),0,-1),0),2)) | R21: =IF(ISBLANK(I21),"",IFERROR(_xlfn.XLOOKUP(I21,Справ_ВидыПремий!$B:$B,Справ_ВидыПремий!$I:$I),""))
C22: =IF(ISBLANK(B22),"",IFERROR(_xlfn.XLOOKUP(B22,Справ_Сотрудников!$B:$B,Справ_Сотрудников!$A:$A),"")) | D22: =IF(ISBLANK(B22),"",IFERROR(_xlfn.XLOOKUP(B22,Справ_Сотрудников!$B:$B,Справ_Сотрудников!$C:$C),"")) | E22: =IF(ISBLANK(B22),"",IFERROR(_xlfn.XLOOKUP(B22,Справ_Сотрудников!$B:$B,Справ_Сотрудников!$D:$D),"")) | F22: =IF(ISBLANK(B22),"",IFERROR(_xlfn.XLOOKUP(B22,Справ_Сотрудников!$B:$B,Справ_Сотрудников!$E:$E),"")) | G22: =IF(ISBLANK(B22),"",IFERROR(_xlfn.XLOOKUP(B22,Справ_Сотрудников!$B:$B,Справ_Сотрудников!$F:$F),"")) | H22: =IF(ISBLANK(B22),"",IFERROR(_xlfn.XLOOKUP(B22,Справ_Сотрудников!$B:$B,Справ_Сотрудников!$G:$G),"")) | J22: =IF(ISBLANK(I22),"",IFERROR(_xlfn.XLOOKUP(I22,Справ_ВидыПремий!$B:$B,Справ_ВидыПремий!$E:$E)&"","")) | K22: =IF(ISBLANK(I22),"",IFERROR(_xlfn.XLOOKUP(I22,Справ_ВидыПремий!$B:$B,Справ_ВидыПремий!$F:$F)&"","")) | M22: =IF(ISBLANK(I22),"",IFERROR(_xlfn.XLOOKUP(I22,Справ_ВидыПремий!$B:$B,Справ_ВидыПремий!$G:$G)&"","")) | N22: =IF(ISBLANK(I22),"",IFERROR(_xlfn.XLOOKUP(I22,Справ_ВидыПремий!$B:$B,Справ_ВидыПремий!$H:$H)&"","")) | P22: =IF(ISBLANK(A22),"",IFERROR(_xlfn.XLOOKUP(A22,Периоды!$A:$A,Периоды!$B:$B),"")) | Q22: =IF(OR(ISBLANK(I22),R22="",ISBLANK(L22)),"",ROUND(IF(IFERROR(_xlfn.XLOOKUP(L22,INDIRECT("'"&R22&"'!$C:$C"),INDIRECT("'"&R22&"'!$G:$G"),"",-1),"")="% выполнения",L22/100,IFERROR(_xlfn.XLOOKUP(L22,INDIRECT("'"&R22&"'!$C:$C"),INDIRECT("'"&R22&"'!$E:$E"),0,-1),0))*IF(ISBLANK(O22),L22,O22)+IFERROR(_xlfn.XLOOKUP(L22,INDIRECT("'"&R22&"'!$C:$C"),INDIRECT("'"&R22&"'!$F:$F"),0,-1),0),2)) | R22: =IF(ISBLANK(I22),"",IFERROR(_xlfn.XLOOKUP(I22,Справ_ВидыПремий!$B:$B,Справ_ВидыПремий!$I:$I),""))
... C50: =IF(ISBLANK(B50),"",IFERROR(_xlfn.XLOOKUP(B50,Справ_Сотрудников!$B:$B,Справ_Сотрудников!$A:$A),"")) | D50: =IF(ISBLANK(B50),"",IFERROR(_xlfn.XLOOKUP(B50,Справ_Сотрудников!$B:$B,Справ_Сотрудников!$C:$C),"")) | E50: =IF(ISBLANK(B50),"",IFERROR(_xlfn.XLOOKUP(B50,Справ_Сотрудников!$B:$B,Справ_Сотрудников!$D:$D),"")) | F50: =IF(ISBLANK(B50),"",IFERROR(_xlfn.XLOOKUP(B50,Справ_Сотрудников!$B:$B,Справ_Сотрудников!$E:$E),"")) | G50: =IF(ISBLANK(B50),"",IFERROR(_xlfn.XLOOKUP(B50,Справ_Сотрудников!$B:$B,Справ_Сотрудников!$F:$F),"")) | H50: =IF(ISBLANK(B50),"",IFERROR(_xlfn.XLOOKUP(B50,Справ_Сотрудников!$B:$B,Справ_Сотрудников!$G:$G),"")) | J50: =IF(ISBLANK(I50),"",IFERROR(_xlfn.XLOOKUP(I50,Справ_ВидыПремий!$B:$B,Справ_ВидыПремий!$E:$E)&"","")) | K50: =IF(ISBLANK(I50),"",IFERROR(_xlfn.XLOOKUP(I50,Справ_ВидыПремий!$B:$B,Справ_ВидыПремий!$F:$F)&"","")) | M50: =IF(ISBLANK(I50),"",IFERROR(_xlfn.XLOOKUP(I50,Справ_ВидыПремий!$B:$B,Справ_ВидыПремий!$G:$G)&"","")) | N50: =IF(ISBLANK(I50),"",IFERROR(_xlfn.XLOOKUP(I50,Справ_ВидыПремий!$B:$B,Справ_ВидыПремий!$H:$H)&"","")) | P50: =IF(ISBLANK(A50),"",IFERROR(_xlfn.XLOOKUP(A50,Периоды!$A:$A,Периоды!$B:$B),"")) | Q50: =IF(OR(ISBLANK(I50),R50="",ISBLANK(L50)),"",ROUND(IF(IFERROR(_xlfn.XLOOKUP(L50,INDIRECT("'"&R50&"'!$C:$C"),INDIRECT("'"&R50&"'!$G:$G"),"",-1),"")="% выполнения",L50/100,IFERROR(_xlfn.XLOOKUP(L50,INDIRECT("'"&R50&"'!$C:$C"),INDIRECT("'"&R50&"'!$E:$E"),0,-1),0))*IF(ISBLANK(O50),L50,O50)+IFERROR(_xlfn.XLOOKUP(L50,INDIRECT("'"&R50&"'!$C:$C"),INDIRECT("'"&R50&"'!$F:$F"),0,-1),0),2)) | R50: =IF(ISBLANK(I50),"",IFERROR(_xlfn.XLOOKUP(I50,Справ_ВидыПремий!$B:$B,Справ_ВидыПремий!$I:$I),""))

Sheet Справ_ВидыПремий
A1: код_вида_премии | B1: название_вида_премии | C1: период_выплаты | D1: должность | E1: вх_параметр_1_название | F1: ед_изм_вх_параметр_1 | G1: KPI | H1: ед_изм_вх_параметр_2 | I1: лист_шкалы | J1: ключ_списка
A2: BT-001 | B2: Премия за количество новых АМ | C2: ЕЖЕМЕСЯЧНО | D2: Менеджер по продажам новых АМ | E2: Кол-во проданных автомобилей | F2: ед. | I2: BT-001_Премия_КолвоАМ | J2: =IF(B2="","",D2&"|"&C2) -> Менеджер по продажам новых АМ|ЕЖЕМЕСЯЧНО
A3: BT-002 | B3: Премия за кумулятивную маржу | C3: ЕЖЕМЕСЯЧНО | D3: Менеджер по продажам новых АМ | E3: Кол-во проданных автомобилей | F3: ед. | G3: Кумулятивная маржа при продаже нового АМ | H3: руб. | I3: BT-002_Премия_КумМаржа | J3: =IF(B3="","",D3&"|"&C3) -> Менеджер по продажам новых АМ|ЕЖЕМЕСЯЧНО
A4: BT-003 | B4: Премия за маржу сервиса | C4: ЕЖЕМЕСЯЧНО | D4: Мастер-консультант | E4: % выполнения плана | F4: % | G4: Маржа от продажи сервисных услуг | H4: руб. | I4: BT-003_Премия_МаржаСервис | J4: =IF(B4="","",D4&"|"&C4) -> Мастер-консультант|ЕЖЕМЕСЯЧНО
A5: BT-004 | B5: Поквартальная премия от продажи финансовых услуг | C5: ЕЖЕКВАРТАЛЬНО | D5: Менеджер по продажам новых АМ | E5: % выполнения плана | F5: % | G5: Плановое значение премии за КВ от продажи финансовых услуг | H5: руб. | I5: BT-004_Премия_КВФин | J5: =IF(B5="","",D5&"|"&C5) -> Менеджер по продажам новых АМ|ЕЖЕКВАРТАЛЬНО
A6: BT-004 | B6: Поквартальная премия от продажи финансовых услуг | C6: ЕЖЕКВАРТАЛЬНО | D6: Менеджер по кредитованию и страхованию | E6: % выполнения плана | F6: % | G6: Плановое значение премии за КВ от продажи финансовых услуг | H6: руб. | I6: BT-004_Премия_КВФин | J6: =IF(B6="","",D6&"|"&C6) -> Менеджер по кредитованию и страхованию|ЕЖЕКВАРТАЛЬНО
J7: =IF(B7="","",D7&"|"&C7)
J8: =IF(B8="","",D8&"|"&C8)
J9: =IF(B9="","",D9&"|"&C9)
J10: =IF(B10="","",D10&"|"&C10)
J11: =IF(B11="","",D11&"|"&C11)
J12: =IF(B12="","",D12&"|"&C12)
J13: =IF(B13="","",D13&"|"&C13)
J14: =IF(B14="","",D14&"|"&C14)
J15: =IF(B15="","",D15&"|"&C15)
J16: =IF(B16="","",D16&"|"&C16)
J17: =IF(B17="","",D17&"|"&C17)
J18: =IF(B18="","",D18&"|"&C18)
... J100: =IF(B100="","",D100&"|"&C100)

Sheet BT-001_Премия_КолвоАМ
A1: шкала_расчета | B1: название_премии | C1: диапазон_от | D1: диапазон_до | E1: множитель | F1: постоянная_часть | G1: тип_множителя
A2: SCALE-001 | B2: BT-001 Премия за количество новых АМ | C2: 0 | D2: 2 | E2: 0 | F2: 0 | G2: Число
A3: SCALE-002 | B3: BT-001 Премия за количество новых АМ | C3: 3 | D3: 5 | E3: 10000 | F3: 0 | G3: Число
A4: SCALE-003 | B4: BT-001 Премия за количество новых АМ | C4: 6 | D4: 15 | E4: 15000 | F4: 0 | G4: Число
A5: SCALE-004 | B5: BT-001 Премия за количество новых АМ | C5: 15 | D5: 999999 | E5: 17000 | F5: 0 | G5: Число

Sheet BT-002_Премия_КумМаржа
A1: шкала_расчета | B1: название_премии | C1: диапазон_от | D1: диапазон_до | E1: множитель | F1: постоянная_часть | G1: тип_множителя
A2: SCALE-005 | B2: BT-002 Премия за кумулятивную маржу при продаже новых АМ | C2: 0 | D2: 2 | E2: 0 | F2: 0 | G2: Число
A3: SCALE-006 | B3: BT-002 Премия за кумулятивную маржу при продаже новых АМ | C3: 3 | D3: 5 | E3: 0.02 | F3: 0 | G3: Число
A4: SCALE-007 | B4: BT-002 Премия за кумулятивную маржу при продаже новых АМ | C4: 6 | D4: 15 | E4: 0.04 | F4: 0 | G4: Число
A5: SCALE-008 | B5: BT-002 Премия за кумулятивную маржу при продаже новых АМ | C5: 15 | D5: 999999 | E5: 0.05 | F5: 0 | G5: Число

Sheet BT-003_Премия_МаржаСервис
A1: шкала_расчета | B1: название_премии | C1: диапазон_от | D1: диапазон_до | E1: множитель | F1: постоянная_часть | G1: тип_множителя
A2: SCALE-009 | B2: BT-003 Премия за маржу от продажи сервисных услуг | C2: 0 | D2: 80 | E2: 0 | F2: 0 | G2: Число
A3: SCALE-010 | B3: BT-003 Премия за маржу от продажи сервисных услуг | C3: 80 | D3: 120 | E3: 1 | F3: 0 | G3: % выполнения
A4: SCALE-011 | B4: BT-003 Премия за маржу от продажи сервисных услуг | C4: 120 | D4: 999999 | E4: 1.2 | F4: 0 | G4: Число

Sheet BT-004_Премия_КВФин
A1: шкала_расчета | B1: название_премии | C1: диапазон_от | D1: диапазон_до | E1: множитель | F1: постоянная_часть | G1: тип_множителя
A2: SCALE-012 | B2: BT-004 Премия за КВ от продажи финансовых услуг | C2: 0 | D2: 80 | E2: 0.5 | F2: 0 | G2: Число
A3: SCALE-013 | B3: BT-004 Премия за КВ от продажи финансовых услуг | C3: 80 | D3: 120 | E3: 1 | F3: 0 | G3: % выполнения
A4: SCALE-014 | B4: BT-004 Премия за КВ от продажи финансовых услуг | C4: 120 | D4: 999999 | E4: 1.2 | F4: 0 | G4: Число

Sheet Справ_Сотрудников
A1: таб_номер | B1: фио_сотрудника | C1: ДЦ | D1: ЦФО | E1: подразделение | F1: должность | G1: марка
A2: 10001 | B2: Иванов Алексей Петрович | C2: ДЦ Север | D2: Продажи новых АМ | E2: Отдел продаж новых АМ | F2: Менеджер по продажам новых АМ | G2: Haval
A3: 10002 | B3: Смирнова Елена Сергеевна | C3: ДЦ Север | D3: Продажи новых АМ | E3: Отдел продаж новых АМ | F3: Менеджер по продажам новых АМ | G3: Chery
A4: 10003 | B4: Петров Игорь Владимирович | C4: ДЦ Север | D4: Финансовые услуги | E4: Отдел кредитования и страхования | F4: Менеджер по кредитованию и страхованию | G4: ЛюбаяМарка
A5: 10004 | B5: Козлова Мария Андреевна | C5: ДЦ Север | D5: Сервис | E5: Сервисный центр | F5: Мастер-консультант | G5: Haval
A6: 10005 | B6: Новиков Дмитрий Сергеевич | C6: ДЦ Юг | D6: Продажи новых АМ | E6: Отдел продаж новых АМ | F6: Менеджер по продажам новых АМ | G6: Geely
A7: 10006 | B7: Морозова Анна Павловна | C7: ДЦ Юг | D7: Сервис | E7: Сервисный центр | F7: Мастер-консультант | G7: ЛюбаяМарка
A8: 10007 | B8: Лебедев Константин Юрьевич | C8: ДЦ Запад | D8: Финансовые услуги | E8: Отдел кредитования и страхования | F8: Менеджер по кредитованию и страхованию | G8: ЛюбаяМарка

Sheet Периоды
A1: календар_период | B1: период_выплаты
A2: 46266 | B2: ЕЖЕМЕСЯЧНО
A3: 46296 | B3: ЕЖЕМЕСЯЧНО
A4: 46327 | B4: ЕЖЕМЕСЯЧНО
A5: 46357 | B5: ЕЖЕМЕСЯЧНО
A6: Q1 2026 | B6: ЕЖЕКВАРТАЛЬНО
A7: Q2 2026 | B7: ЕЖЕКВАРТАЛЬНО
A8: Q3 2026 | B8: ЕЖЕКВАРТАЛЬНО
A9: Q4 2026 | B9: ЕЖЕКВАРТАЛЬНО

Sheet ETL
A1: строка_ПОТ | B1: период | C1: тип_периода | D1: таб_номер | E1: фио_сотрудника | F1: ДЦ | G1: ЦФО | H1: подразделение | I1: должность | J1: марка | K1: код_вида_премии | L1: вид_премии | M1: лист_шкалы | N1: вх_параметр_1_название | O1: ед_изм_1 | P1: вх_параметр_1_значение | Q1: KPI_название | R1: KPI_ед.изм. | S1: KPI_значение | T1: код_шкалы | U1: диапазон_от | V1: диапазон_до | W1: множитель | X1: постоянная_часть | Y1: премия_руб | Z1: тип_множителя
A2: =IF(ISBLANK(ПОТ!$B2),"",ROW(ПОТ!$B2)) -> 2 | B2: =IF(ISBLANK(ПОТ!$A2),"",ПОТ!$A2) -> 46266 | C2: =ПОТ!$P2 -> ЕЖЕМЕСЯЧНО | D2: =ПОТ!$C2 -> 10001 | E2: =IF(ISBLANK(ПОТ!$B2),"",ПОТ!$B2) -> Иванов Алексей Петрович | F2: =ПОТ!$D2 -> ДЦ Север | G2: =ПОТ!$E2 -> Продажи новых АМ | H2: =ПОТ!$F2 -> Отдел продаж новых АМ | I2: =ПОТ!$G2 -> Менеджер по продажам новых АМ | J2: =ПОТ!$H2 -> Haval | K2: =IF(ISBLANK(ПОТ!$I2),"",IFERROR(_xlfn.XLOOKUP(ПОТ!$I2,Справ_ВидыПремий!$B:$B,Справ_ВидыПремий!$A:$A),"")) -> BT-001 | L2: =IF(ISBLANK(ПОТ!$I2),"",ПОТ!$I2) -> Премия за количество новых АМ | M2: =ПОТ!$R2 -> BT-001_Премия_КолвоАМ | N2: =ПОТ!$J2 -> Кол-во проданных автомобилей | O2: =ПОТ!$K2 -> ед. | P2: =IF(ISBLANK(ПОТ!$L2),"",ПОТ!$L2) -> 10 | Q2: =ПОТ!$M2 | R2: =ПОТ!$N2 | S2: =IF(ISBLANK(ПОТ!$O2),"",ПОТ!$O2) | T2: =IF(ПОТ!$R2="","",IFERROR(_xlfn.XLOOKUP(ПОТ!$L2,INDIRECT("'"&ПОТ!$R2&"'!$C:$C"),INDIRECT("'"&ПОТ!$R2&"'!$A:$A"),"",-1),"")) -> SCALE-003 | U2: =IF(ПОТ!$R2="","",IFERROR(_xlfn.XLOOKUP(ПОТ!$L2,INDIRECT("'"&ПОТ!$R2&"'!$C:$C"),INDIRECT("'"&ПОТ!$R2&"'!$C:$C"),"",-1),"")) -> 6 | V2: =IF(ПОТ!$R2="","",IFERROR(_xlfn.XLOOKUP(ПОТ!$L2,INDIRECT("'"&ПОТ!$R2&"'!$C:$C"),INDIRECT("'"&ПОТ!$R2&"'!$D:$D"),"",-1),"")) -> 15 | W2: =IF(ПОТ!$R2="","",IF(IFERROR(_xlfn.XLOOKUP(ПОТ!$L2,INDIRECT("'"&ПОТ!$R2&"'!$C:$C"),INDIRECT("'"&ПОТ!$R2&"'!$G:$G"),"",-1),"")="% выполнения",ПОТ!$L2/100,IFERROR(_xlfn.XLOOKUP(ПОТ!$L2,INDIRECT("'"&ПОТ!$R2&"'!$C:$C"),INDIRECT("'"&ПОТ!$R2&"'!$E:$E"),"",-1),""))) -> 15000 | X2: =IF(ПОТ!$R2="","",IFERROR(_xlfn.XLOOKUP(ПОТ!$L2,INDIRECT("'"&ПОТ!$R2&"'!$C:$C"),INDIRECT("'"&ПОТ!$R2&"'!$F:$F"),"",-1),"")) -> 0 | Y2: =ПОТ!$Q2 -> 150000 | Z2: =IF(ПОТ!$R2="","",IFERROR(_xlfn.XLOOKUP(ПОТ!$L2,INDIRECT("'"&ПОТ!$R2&"'!$C:$C"),INDIRECT("'"&ПОТ!$R2&"'!$G:$G"),"",-1),"")) -> Число
A3: =IF(ISBLANK(ПОТ!$B3),"",ROW(ПОТ!$B3)) -> 3 | B3: =IF(ISBLANK(ПОТ!$A3),"",ПОТ!$A3) -> Q3 2026 | C3: =ПОТ!$P3 -> ЕЖЕКВАРТАЛЬНО | D3: =ПОТ!$C3 -> 10003 | E3: =IF(ISBLANK(ПОТ!$B3),"",ПОТ!$B3) -> Петров Игорь Владимирович | F3: =ПОТ!$D3 -> ДЦ Север | G3: =ПОТ!$E3 -> Финансовые услуги | H3: =ПОТ!$F3 -> Отдел кредитования и страхования | I3: =ПОТ!$G3 -> Менеджер по кредитованию и страхованию | J3: =ПОТ!$H3 -> ЛюбаяМарка | K3: =IF(ISBLANK(ПОТ!$I3),"",IFERROR(_xlfn.XLOOKUP(ПОТ!$I3,Справ_ВидыПремий!$B:$B,Справ_ВидыПремий!$A:$A),"")) -> BT-004 | L3: =IF(ISBLANK(ПОТ!$I3),"",ПОТ!$I3) -> Поквартальная премия от продажи финансовых услуг | M3: =ПОТ!$R3 -> BT-004_Премия_КВФин | N3: =ПОТ!$J3 -> % выполнения плана | O3: =ПОТ!$K3 -> % | P3: =IF(ISBLANK(ПОТ!$L3),"",ПОТ!$L3) -> 100 | Q3: =ПОТ!$M3 -> Плановое значение премии за КВ от продажи финансовых услуг | R3: =ПОТ!$N3 -> руб. | S3: =IF(ISBLANK(ПОТ!$O3),"",ПОТ!$O3) -> 50000 | T3: =IF(ПОТ!$R3="","",IFERROR(_xlfn.XLOOKUP(ПОТ!$L3,INDIRECT("'"&ПОТ!$R3&"'!$C:$C"),INDIRECT("'"&ПОТ!$R3&"'!$A:$A"),"",-1),"")) -> SCALE-013 | U3: =IF(ПОТ!$R3="","",IFERROR(_xlfn.XLOOKUP(ПОТ!$L3,INDIRECT("'"&ПОТ!$R3&"'!$C:$C"),INDIRECT("'"&ПОТ!$R3&"'!$C:$C"),"",-1),"")) -> 80 | V3: =IF(ПОТ!$R3="","",IFERROR(_xlfn.XLOOKUP(ПОТ!$L3,INDIRECT("'"&ПОТ!$R3&"'!$C:$C"),INDIRECT("'"&ПОТ!$R3&"'!$D:$D"),"",-1),"")) -> 120 | W3: =IF(ПОТ!$R3="","",IF(IFERROR(_xlfn.XLOOKUP(ПОТ!$L3,INDIRECT("'"&ПОТ!$R3&"'!$C:$C"),INDIRECT("'"&ПОТ!$R3&"'!$G:$G"),"",-1),"")="% выполнения",ПОТ!$L3/100,IFERROR(_xlfn.XLOOKUP(ПОТ!$L3,INDIRECT("'"&ПОТ!$R3&"'!$C:$C"),INDIRECT("'"&ПОТ!$R3&"'!$E:$E"),"",-1),""))) -> 1 | X3: =IF(ПОТ!$R3="","",IFERROR(_xlfn.XLOOKUP(ПОТ!$L3,INDIRECT("'"&ПОТ!$R3&"'!$C:$C"),INDIRECT("'"&ПОТ!$R3&"'!$F:$F"),"",-1),"")) -> 0 | Y3: =ПОТ!$Q3 -> 50000 | Z3: =IF(ПОТ!$R3="","",IFERROR(_xlfn.XLOOKUP(ПОТ!$L3,INDIRECT("'"&ПОТ!$R3&"'!$C:$C"),INDIRECT("'"&ПОТ!$R3&"'!$G:$G"),"",-1),"")) -> % выполнения
A4: =IF(ISBLANK(ПОТ!$B4),"",ROW(ПОТ!$B4)) -> 4 | B4: =IF(ISBLANK(ПОТ!$A4),"",ПОТ!$A4) -> Q3 2026 | C4: =ПОТ!$P4 -> ЕЖЕКВАРТАЛЬНО | D4: =ПОТ!$C4 -> 10003 | E4: =IF(ISBLANK(ПОТ!$B4),"",ПОТ!$B4) -> Петров Игорь Владимирович | F4: =ПОТ!$D4 -> ДЦ Север | G4: =ПОТ!$E4 -> Финансовые услуги | H4: =ПОТ!$F4 -> Отдел кредитования и страхования | I4: =ПОТ!$G4 -> Менеджер по кредитованию и страхованию | J4: =ПОТ!$H4 -> ЛюбаяМарка | K4: =IF(ISBLANK(ПОТ!$I4),"",IFERROR(_xlfn.XLOOKUP(ПОТ!$I4,Справ_ВидыПремий!$B:$B,Справ_ВидыПремий!$A:$A),"")) -> BT-004 | L4: =IF(ISBLANK(ПОТ!$I4),"",ПОТ!$I4) -> Поквартальная премия от продажи финансовых услуг | M4: =ПОТ!$R4 -> BT-004_Премия_КВФин | N4: =ПОТ!$J4 -> % выполнения плана | O4: =ПОТ!$K4 -> % | P4: =IF(ISBLANK(ПОТ!$L4),"",ПОТ!$L4) -> 120 | Q4: =ПОТ!$M4 -> Плановое значение премии за КВ от продажи финансовых услуг | R4: =ПОТ!$N4 -> руб. | S4: =IF(ISBLANK(ПОТ!$O4),"",ПОТ!$O4) -> 50000 | T4: =IF(ПОТ!$R4="","",IFERROR(_xlfn.XLOOKUP(ПОТ!$L4,INDIRECT("'"&ПОТ!$R4&"'!$C:$C"),INDIRECT("'"&ПОТ!$R4&"'!$A:$A"),"",-1),"")) -> SCALE-014 | U4: =IF(ПОТ!$R4="","",IFERROR(_xlfn.XLOOKUP(ПОТ!$L4,INDIRECT("'"&ПОТ!$R4&"'!$C:$C"),INDIRECT("'"&ПОТ!$R4&"'!$C:$C"),"",-1),"")) -> 120 | V4: =IF(ПОТ!$R4="","",IFERROR(_xlfn.XLOOKUP(ПОТ!$L4,INDIRECT("'"&ПОТ!$R4&"'!$C:$C"),INDIRECT("'"&ПОТ!$R4&"'!$D:$D"),"",-1),"")) -> 999999 | W4: =IF(ПОТ!$R4="","",IF(IFERROR(_xlfn.XLOOKUP(ПОТ!$L4,INDIRECT("'"&ПОТ!$R4&"'!$C:$C"),INDIRECT("'"&ПОТ!$R4&"'!$G:$G"),"",-1),"")="% выполнения",ПОТ!$L4/100,IFERROR(_xlfn.XLOOKUP(ПОТ!$L4,INDIRECT("'"&ПОТ!$R4&"'!$C:$C"),INDIRECT("'"&ПОТ!$R4&"'!$E:$E"),"",-1),""))) -> 1.2 | X4: =IF(ПОТ!$R4="","",IFERROR(_xlfn.XLOOKUP(ПОТ!$L4,INDIRECT("'"&ПОТ!$R4&"'!$C:$C"),INDIRECT("'"&ПОТ!$R4&"'!$F:$F"),"",-1),"")) -> 0 | Y4: =ПОТ!$Q4 -> 60000 | Z4: =IF(ПОТ!$R4="","",IFERROR(_xlfn.XLOOKUP(ПОТ!$L4,INDIRECT("'"&ПОТ!$R4&"'!$C:$C"),INDIRECT("'"&ПОТ!$R4&"'!$G:$G"),"",-1),"")) -> Число
A5: =IF(ISBLANK(ПОТ!$B5),"",ROW(ПОТ!$B5)) -> 5 | B5: =IF(ISBLANK(ПОТ!$A5),"",ПОТ!$A5) -> Q3 2026 | C5: =ПОТ!$P5 -> ЕЖЕКВАРТАЛЬНО | D5: =ПОТ!$C5 -> 10007 | E5: =IF(ISBLANK(ПОТ!$B5),"",ПОТ!$B5) -> Лебедев Константин Юрьевич | F5: =ПОТ!$D5 -> ДЦ Запад | G5: =ПОТ!$E5 -> Финансовые услуги | H5: =ПОТ!$F5 -> Отдел кредитования и страхования | I5: =ПОТ!$G5 -> Менеджер по кредитованию и страхованию | J5: =ПОТ!$H5 -> ЛюбаяМарка | K5: =IF(ISBLANK(ПОТ!$I5),"",IFERROR(_xlfn.XLOOKUP(ПОТ!$I5,Справ_ВидыПремий!$B:$B,Справ_ВидыПремий!$A:$A),"")) -> BT-004 | L5: =IF(ISBLANK(ПОТ!$I5),"",ПОТ!$I5) -> Поквартальная премия от продажи финансовых услуг | M5: =ПОТ!$R5 -> BT-004_Премия_КВФин | N5: =ПОТ!$J5 -> % выполнения плана | O5: =ПОТ!$K5 -> % | P5: =IF(ISBLANK(ПОТ!$L5),"",ПОТ!$L5) -> 76 | Q5: =ПОТ!$M5 -> Плановое значение премии за КВ от продажи финансовых услуг | R5: =ПОТ!$N5 -> руб. | S5: =IF(ISBLANK(ПОТ!$O5),"",ПОТ!$O5) -> 50000 | T5: =IF(ПОТ!$R5="","",IFERROR(_xlfn.XLOOKUP(ПОТ!$L5,INDIRECT("'"&ПОТ!$R5&"'!$C:$C"),INDIRECT("'"&ПОТ!$R5&"'!$A:$A"),"",-1),"")) -> SCALE-012 | U5: =IF(ПОТ!$R5="","",IFERROR(_xlfn.XLOOKUP(ПОТ!$L5,INDIRECT("'"&ПОТ!$R5&"'!$C:$C"),INDIRECT("'"&ПОТ!$R5&"'!$C:$C"),"",-1),"")) -> 0 | V5: =IF(ПОТ!$R5="","",IFERROR(_xlfn.XLOOKUP(ПОТ!$L5,INDIRECT("'"&ПОТ!$R5&"'!$C:$C"),INDIRECT("'"&ПОТ!$R5&"'!$D:$D"),"",-1),"")) -> 80 | W5: =IF(ПОТ!$R5="","",IF(IFERROR(_xlfn.XLOOKUP(ПОТ!$L5,INDIRECT("'"&ПОТ!$R5&"'!$C:$C"),INDIRECT("'"&ПОТ!$R5&"'!$G:$G"),"",-1),"")="% выполнения",ПОТ!$L5/100,IFERROR(_xlfn.XLOOKUP(ПОТ!$L5,INDIRECT("'"&ПОТ!$R5&"'!$C:$C"),INDIRECT("'"&ПОТ!$R5&"'!$E:$E"),"",-1),""))) -> 0.5 | X5: =IF(ПОТ!$R5="","",IFERROR(_xlfn.XLOOKUP(ПОТ!$L5,INDIRECT("'"&ПОТ!$R5&"'!$C:$C"),INDIRECT("'"&ПОТ!$R5&"'!$F:$F"),"",-1),"")) -> 0 | Y5: =ПОТ!$Q5 -> 25000 | Z5: =IF(ПОТ!$R5="","",IFERROR(_xlfn.XLOOKUP(ПОТ!$L5,INDIRECT("'"&ПОТ!$R5&"'!$C:$C"),INDIRECT("'"&ПОТ!$R5&"'!$G:$G"),"",-1),"")) -> Число
A6: =IF(ISBLANK(ПОТ!$B6),"",ROW(ПОТ!$B6)) -> 6 | B6: =IF(ISBLANK(ПОТ!$A6),"",ПОТ!$A6) -> 46327 | C6: =ПОТ!$P6 -> ЕЖЕМЕСЯЧНО | D6: =ПОТ!$C6 -> 10002 | E6: =IF(ISBLANK(ПОТ!$B6),"",ПОТ!$B6) -> Смирнова Елена Сергеевна | F6: =ПОТ!$D6 -> ДЦ Север | G6: =ПОТ!$E6 -> Продажи новых АМ | H6: =ПОТ!$F6 -> Отдел продаж новых АМ | I6: =ПОТ!$G6 -> Менеджер по продажам новых АМ | J6: =ПОТ!$H6 -> Chery | K6: =IF(ISBLANK(ПОТ!$I6),"",IFERROR(_xlfn.XLOOKUP(ПОТ!$I6,Справ_ВидыПремий!$B:$B,Справ_ВидыПремий!$A:$A),"")) -> BT-001 | L6: =IF(ISBLANK(ПОТ!$I6),"",ПОТ!$I6) -> Премия за количество новых АМ | M6: =ПОТ!$R6 -> BT-001_Премия_КолвоАМ | N6: =ПОТ!$J6 -> Кол-во проданных автомобилей | O6: =ПОТ!$K6 -> ед. | P6: =IF(ISBLANK(ПОТ!$L6),"",ПОТ!$L6) -> 30 | Q6: =ПОТ!$M6 | R6: =ПОТ!$N6 | S6: =IF(ISBLANK(ПОТ!$O6),"",ПОТ!$O6) | T6: =IF(ПОТ!$R6="","",IFERROR(_xlfn.XLOOKUP(ПОТ!$L6,INDIRECT("'"&ПОТ!$R6&"'!$C:$C"),INDIRECT("'"&ПОТ!$R6&"'!$A:$A"),"",-1),"")) -> SCALE-004 | U6: =IF(ПОТ!$R6="","",IFERROR(_xlfn.XLOOKUP(ПОТ!$L6,INDIRECT("'"&ПОТ!$R6&"'!$C:$C"),INDIRECT("'"&ПОТ!$R6&"'!$C:$C"),"",-1),"")) -> 15 | V6: =IF(ПОТ!$R6="","",IFERROR(_xlfn.XLOOKUP(ПОТ!$L6,INDIRECT("'"&ПОТ!$R6&"'!$C:$C"),INDIRECT("'"&ПОТ!$R6&"'!$D:$D"),"",-1),"")) -> 999999 | W6: =IF(ПОТ!$R6="","",IF(IFERROR(_xlfn.XLOOKUP(ПОТ!$L6,INDIRECT("'"&ПОТ!$R6&"'!$C:$C"),INDIRECT("'"&ПОТ!$R6&"'!$G:$G"),"",-1),"")="% выполнения",ПОТ!$L6/100,IFERROR(_xlfn.XLOOKUP(ПОТ!$L6,INDIRECT("'"&ПОТ!$R6&"'!$C:$C"),INDIRECT("'"&ПОТ!$R6&"'!$E:$E"),"",-1),""))) -> 17000 | X6: =IF(ПОТ!$R6="","",IFERROR(_xlfn.XLOOKUP(ПОТ!$L6,INDIRECT("'"&ПОТ!$R6&"'!$C:$C"),INDIRECT("'"&ПОТ!$R6&"'!$F:$F"),"",-1),"")) -> 0 | Y6: =ПОТ!$Q6 -> 510000 | Z6: =IF(ПОТ!$R6="","",IFERROR(_xlfn.XLOOKUP(ПОТ!$L6,INDIRECT("'"&ПОТ!$R6&"'!$C:$C"),INDIRECT("'"&ПОТ!$R6&"'!$G:$G"),"",-1),"")) -> Число
A7: =IF(ISBLANK(ПОТ!$B7),"",ROW(ПОТ!$B7)) -> 7 | B7: =IF(ISBLANK(ПОТ!$A7),"",ПОТ!$A7) -> 46357 | C7: =ПОТ!$P7 -> ЕЖЕМЕСЯЧНО | D7: =ПОТ!$C7 -> 10006 | E7: =IF(ISBLANK(ПОТ!$B7),"",ПОТ!$B7) -> Морозова Анна Павловна | F7: =ПОТ!$D7 -> ДЦ Юг | G7: =ПОТ!$E7 -> Сервис | H7: =ПОТ!$F7 -> Сервисный центр | I7: =ПОТ!$G7 -> Мастер-консультант | J7: =ПОТ!$H7 -> ЛюбаяМарка | K7: =IF(ISBLANK(ПОТ!$I7),"",IFERROR(_xlfn.XLOOKUP(ПОТ!$I7,Справ_ВидыПремий!$B:$B,Справ_ВидыПремий!$A:$A),"")) -> BT-003 | L7: =IF(ISBLANK(ПОТ!$I7),"",ПОТ!$I7) -> Премия за маржу сервиса | M7: =ПОТ!$R7 -> BT-003_Премия_МаржаСервис | N7: =ПОТ!$J7 -> % выполнения плана | O7: =ПОТ!$K7 -> % | P7: =IF(ISBLANK(ПОТ!$L7),"",ПОТ!$L7) -> 140 | Q7: =ПОТ!$M7 -> Маржа от продажи сервисных услуг | R7: =ПОТ!$N7 -> руб. | S7: =IF(ISBLANK(ПОТ!$O7),"",ПОТ!$O7) -> 800000 | T7: =IF(ПОТ!$R7="","",IFERROR(_xlfn.XLOOKUP(ПОТ!$L7,INDIRECT("'"&ПОТ!$R7&"'!$C:$C"),INDIRECT("'"&ПОТ!$R7&"'!$A:$A"),"",-1),"")) -> SCALE-011 | U7: =IF(ПОТ!$R7="","",IFERROR(_xlfn.XLOOKUP(ПОТ!$L7,INDIRECT("'"&ПОТ!$R7&"'!$C:$C"),INDIRECT("'"&ПОТ!$R7&"'!$C:$C"),"",-1),"")) -> 120 | V7: =IF(ПОТ!$R7="","",IFERROR(_xlfn.XLOOKUP(ПОТ!$L7,INDIRECT("'"&ПОТ!$R7&"'!$C:$C"),INDIRECT("'"&ПОТ!$R7&"'!$D:$D"),"",-1),"")) -> 999999 | W7: =IF(ПОТ!$R7="","",IF(IFERROR(_xlfn.XLOOKUP(ПОТ!$L7,INDIRECT("'"&ПОТ!$R7&"'!$C:$C"),INDIRECT("'"&ПОТ!$R7&"'!$G:$G"),"",-1),"")="% выполнения",ПОТ!$L7/100,IFERROR(_xlfn.XLOOKUP(ПОТ!$L7,INDIRECT("'"&ПОТ!$R7&"'!$C:$C"),INDIRECT("'"&ПОТ!$R7&"'!$E:$E"),"",-1),""))) -> 1.2 | X7: =IF(ПОТ!$R7="","",IFERROR(_xlfn.XLOOKUP(ПОТ!$L7,INDIRECT("'"&ПОТ!$R7&"'!$C:$C"),INDIRECT("'"&ПОТ!$R7&"'!$F:$F"),"",-1),"")) -> 0 | Y7: =ПОТ!$Q7 -> 960000 | Z7: =IF(ПОТ!$R7="","",IFERROR(_xlfn.XLOOKUP(ПОТ!$L7,INDIRECT("'"&ПОТ!$R7&"'!$C:$C"),INDIRECT("'"&ПОТ!$R7&"'!$G:$G"),"",-1),"")) -> Число
A8: =IF(ISBLANK(ПОТ!$B8),"",ROW(ПОТ!$B8)) -> 8 | B8: =IF(ISBLANK(ПОТ!$A8),"",ПОТ!$A8) -> 46296 | C8: =ПОТ!$P8 -> ЕЖЕМЕСЯЧНО | D8: =ПОТ!$C8 -> 10001 | E8: =IF(ISBLANK(ПОТ!$B8),"",ПОТ!$B8) -> Иванов Алексей Петрович | F8: =ПОТ!$D8 -> ДЦ Север | G8: =ПОТ!$E8 -> Продажи новых АМ | H8: =ПОТ!$F8 -> Отдел продаж новых АМ | I8: =ПОТ!$G8 -> Менеджер по продажам новых АМ | J8: =ПОТ!$H8 -> Haval | K8: =IF(ISBLANK(ПОТ!$I8),"",IFERROR(_xlfn.XLOOKUP(ПОТ!$I8,Справ_ВидыПремий!$B:$B,Справ_ВидыПремий!$A:$A),"")) -> BT-002 | L8: =IF(ISBLANK(ПОТ!$I8),"",ПОТ!$I8) -> Премия за кумулятивную маржу | M8: =ПОТ!$R8 -> BT-002_Премия_КумМаржа | N8: =ПОТ!$J8 -> Кол-во проданных автомобилей | O8: =ПОТ!$K8 -> ед. | P8: =IF(ISBLANK(ПОТ!$L8),"",ПОТ!$L8) -> 12 | Q8: =ПОТ!$M8 -> Кумулятивная маржа при продаже нового АМ | R8: =ПОТ!$N8 -> руб. | S8: =IF(ISBLANK(ПОТ!$O8),"",ПОТ!$O8) -> 12000000 | T8: =IF(ПОТ!$R8="","",IFERROR(_xlfn.XLOOKUP(ПОТ!$L8,INDIRECT("'"&ПОТ!$R8&"'!$C:$C"),INDIRECT("'"&ПОТ!$R8&"'!$A:$A"),"",-1),"")) -> SCALE-007 | U8: =IF(ПОТ!$R8="","",IFERROR(_xlfn.XLOOKUP(ПОТ!$L8,INDIRECT("'"&ПОТ!$R8&"'!$C:$C"),INDIRECT("'"&ПОТ!$R8&"'!$C:$C"),"",-1),"")) -> 6 | V8: =IF(ПОТ!$R8="","",IFERROR(_xlfn.XLOOKUP(ПОТ!$L8,INDIRECT("'"&ПОТ!$R8&"'!$C:$C"),INDIRECT("'"&ПОТ!$R8&"'!$D:$D"),"",-1),"")) -> 15 | W8: =IF(ПОТ!$R8="","",IF(IFERROR(_xlfn.XLOOKUP(ПОТ!$L8,INDIRECT("'"&ПОТ!$R8&"'!$C:$C"),INDIRECT("'"&ПОТ!$R8&"'!$G:$G"),"",-1),"")="% выполнения",ПОТ!$L8/100,IFERROR(_xlfn.XLOOKUP(ПОТ!$L8,INDIRECT("'"&ПОТ!$R8&"'!$C:$C"),INDIRECT("'"&ПОТ!$R8&"'!$E:$E"),"",-1),""))) -> 0.04 | X8: =IF(ПОТ!$R8="","",IFERROR(_xlfn.XLOOKUP(ПОТ!$L8,INDIRECT("'"&ПОТ!$R8&"'!$C:$C"),INDIRECT("'"&ПОТ!$R8&"'!$F:$F"),"",-1),"")) -> 0 | Y8: =ПОТ!$Q8 -> 480000 | Z8: =IF(ПОТ!$R8="","",IFERROR(_xlfn.XLOOKUP(ПОТ!$L8,INDIRECT("'"&ПОТ!$R8&"'!$C:$C"),INDIRECT("'"&ПОТ!$R8&"'!$G:$G"),"",-1),"")) -> Число
